Workbook

Sheet Field Players
A1: Result | B1: Points | E1: Round 1 | I1: Round 2 | M1: Round 3 | Q1: Round 4 | U1: Round 5 | Z1: Round 1 | AD1: Round 2 | AH1: Round 3 | AL1: Round 4 | AP1: Round 5 | AU1: Round 1 | AY1: Round 2 | BC1: Round 3 | BG1: Round 4 | BK1: Round 5 | BP1: Round 1 | BT1: Round 2 | BX1: Round 3 | CB1: Round 4 | CF1: Round 5 | CK1: Round 1 | CO1: Round 2 | CS1: Round 3 | CW1: Round 4 | DA1: Round 5 | DF1: Round 1 | DJ1: Round 2 | DN1: Round 3 | DR1: Round 4 | DV1: Round 5 | EA1: Round 1 | EE1: Round 2 | EI1: Round 3 | EM1: Round 4 | EQ1: Round 5 | EV1: Round 1 | EZ1: Round 2 | FD1: Round 3 | FH1: Round 4
A2: Win | B2: 3 | E2: Team | F2: Score | G2: Team | H2: Score | I2: Team | J2: Score | K2: Team | L2: Score | M2: Team | N2: Score | O2: Team | P2: Score | Q2: Team | R2: Score | S2: Team | T2: Score | U2: Team | V2: Score | W2: Team | X2: Score | Z2: Team | AA2: Score | AB2: Team | AC2: Score | AD2: Team | AE2: Score | AF2: Team | AG2: Score | AH2: Team | AI2: Score | AJ2: Team | AK2: Score | AL2: Team | AM2: Score | AN2: Team | AO2: Score | AP2: Team | AQ2: Score | AR2: Team | AS2: Score | AU2: Team | AV2: Score | AW2: Team | AX2: Score | AY2: Team | AZ2: Score | BA2: Team | BB2: Score | BC2: Team | BD2: Score | BE2: Team | BF2: Score | BG2: Team | BH2: Score | BI2: Team | BJ2: Score | BK2: Team | BL2: Score | BM2: Team | BN2: Score | BP2: Team | BQ2: Score | BR2: Team | BS2: Score | BT2: Team | BU2: Score | BV2: Team | BW2: Score | BX2: Team | BY2: Score | BZ2: Team | CA2: Score | CB2: Team | CC2: Score | CD2: Team | CE2: Score | CF2: Team | CG2: Score | CH2: Team | CI2: Score | CK2: Team | CL2: Score | CM2: Team | CN2: Score | CO2: Team | CP2: Score | CQ2: Team | CR2: Score | CS2: Team | CT2: Score | CU2: Team | CV2: Score | CW2: Team | CX2: Score | CY2: Team | CZ2: Score | DA2: Team | DB2: Score | DC2: Team | DD2: Score | DF2: Team | DG2: Score | DH2: Team | DI2: Score | DJ2: Team | DK2: Score | DL2: Team | DM2: Score | DN2: Team | DO2: Score | DP2: Team | DQ2: Score | DR2: Team | DS2: Score | DT2: Team | DU2: Score | DV2: Team | DW2: Score | DX2: Team | DY2: Score | EA2: Team | EB2: Score | EC2: Team | ED2: Score | EE2: Team | EF2: Score | EG2: Team | EH2: Score | EI2: Team | EJ2: Score | EK2: Team | EL2: Score | EM2: Team | EN2: Score | EO2: Team | EP2: Score | EQ2: Team | ER2: Score | ES2: Team | ET2: Score | EV2: Team | EW2: Score | EX2: Team | EY2: Score | EZ2: Team | FA2: Score | FB2: Team | FC2: Score | FD2: Team | FE2: Score | FF2: Team | FG2: Score | FH2: Team | FI2: Score | FJ2: Team | FK2: Score
A3: Tie | B3: 1 | E3: Pink | F3: 1 | G3: Blue | H3: 6 | I3: Pink | J3: 2 | K3: Blue | L3: 7 | M3: Pink | N3: 0 | O3: Blue | P3: 4 | Q3: Pink | R3: 2 | S3: Blue | T3: 5 | U3: Pink | V3: 6 | W3: Blue | X3: 0 | Z3: Pink | AA3: 3 | AB3: Blue | AC3: 5 | AD3: Pink | AE3: 3 | AF3: Blue | AG3: 1 | AH3: Pink | AI3: 3 | AJ3: Blue | AK3: 3 | AL3: Pink | AM3: 5 | AN3: Blue | AO3: 1 | AP3: Pink | AQ3: 3 | AR3: Blue | AS3: 9 | AU3: Pink | AV3: 4 | AW3: Blue | AX3: 5 | AY3: Pink | AZ3: 6 | BA3: Blue | BB3: 6 | BC3: Pink | BD3: 4 | BE3: Blue | BF3: 2 | BG3: Pink | BH3: 4 | BI3: Blue | BJ3: 2 | BK3: Pink | BL3: 7 | BM3: Blue | BN3: 1 | BP3: Pink | BQ3: 3 | BR3: Blue | BS3: 4 | BT3: Pink | BU3: 7 | BV3: Blue | BW3: 4 | BX3: Pink | BY3: 4 | BZ3: Blue | CA3: 7 | CB3: Pink | CC3: 8 | CD3: Blue | CE3: 2 | CF3: Pink | CG3: 3 | CH3: Blue | CI3: 2 | CK3: Pink | CL3: 1 | CM3: Blue | CN3: 4 | CO3: Pink | CP3: 1 | CQ3: Blue | CR3: 4 | CS3: Pink | CT3: 5 | CU3: Blue | CV3: 5 | CW3: Pink | CX3: 5 | CY3: Blue | CZ3: 2 | DA3: Pink | DB3: 6 | DC3: Blue | DD3: 2 | DF3: Pink | DG3: 3 | DH3: Blue | DI3: 5 | DJ3: Pink | DK3: 10 | DL3: Blue | DM3: 4 | DN3: Pink | DO3: 4 | DP3: Blue | DQ3: 2 | DR3: Pink | DS3: 6 | DT3: Blue | DU3: 3 | DV3: Pink | DW3: 3 | DX3: Blue | DY3: 6 | EA3: Pink | EB3: 8 | EC3: Blue | ED3: 8 | EE3: Pink | EF3: 5 | EG3: Blue | EH3: 1 | EI3: Pink | EJ3: 2 | EK3: Blue | EL3: 1 | EM3: Pink | EN3: 1 | EO3: Blue | EP3: 6 | EQ3: Pink | ER3: 3 | ES3: Blue | ET3: 5 | EV3: Pink | EW3: 1 | EX3: Blue | EY3: 5 | EZ3: Pink | FA3: 4 | FB3: Blue | FC3: 0 | FD3: Pink | FE3: 6 | FF3: Blue | FG3: 1 | FH3: Pink | FI3: 2 | FJ3: Blue | FK3: 6
A4: Loss | B4: 0 | E4: Yellow | F4: 3 | G4: Jerseys | H4: 1 | I4: Yellow | J4: 7 | K4: Jerseys | L4: 1 | M4: Yellow | N4: 4 | O4: Jerseys | P4: 2 | Q4: Yellow | R4: 3 | S4: Jerseys | T4: 6 | U4: Yellow | V4: 5 | W4: Jerseys | X4: 3 | Z4: Yellow | AA4: 3 | AB4: Jerseys | AC4: 5 | AD4: Yellow | AE4: 4 | AF4: Jerseys | AG4: 6 | AH4: Yellow | AI4: 1 | AJ4: Jerseys | AK4: 3 | AL4: Yellow | AM4: 4 | AN4: Jerseys | AO4: 4 | AP4: Yellow | AQ4: 5 | AR4: Jerseys | AS4: 3 | AU4: Yellow | AV4: 5 | AW4: Jerseys | AX4: 1 | AY4: Yellow | AZ4: 8 | BA4: Jerseys | BB4: 0 | BC4: Yellow | BD4: 2 | BE4: Jerseys | BF4: 2 | BG4: Yellow | BH4: 6 | BI4: Jerseys | BJ4: 3 | BK4: Yellow | BL4: 5 | BM4: Jerseys | BN4: 6 | BP4: Yellow | BQ4: 5 | BR4: Jerseys | BS4: 1 | BT4: Yellow | BU4: 5 | BV4: Jerseys | BW4: 1 | BX4: Yellow | BY4: 5 | BZ4: Jerseys | CA4: 7 | CB4: Yellow | CC4: 0 | CD4: Jerseys | CE4: 7 | CF4: Yellow | CG4: 0 | CH4: Jerseys | CI4: 1 | CK4: Yellow | CL4: 2 | CM4: Jerseys | CN4: 4 | CO4: Yellow | CP4: 1 | CQ4: Jerseys | CR4: 2 | CS4: Yellow | CT4: 2 | CU4: Jerseys | CV4: 4 | CW4: Yellow | CX4: 9 | CY4: Jerseys | CZ4: 2 | DA4: Yellow | DB4: 6 | DC4: Jerseys | DD4: 6 | DF4: Yellow | DG4: 4 | DH4: Jerseys | DI4: 5 | DJ4: Yellow | DK4: 3 | DL4: Jerseys | DM4: 4 | DN4: Yellow | DO4: 5 | DP4: Jerseys | DQ4: 3 | DR4: Yellow | DS4: 2 | DT4: Jerseys | DU4: 4 | DV4: Yellow | DW4: 7 | DX4: Jerseys | DY4: 4 | EA4: Yellow | EB4: 4 | EC4: Jerseys | ED4: 4 | EE4: Yellow | EF4: 2 | EG4: Jerseys | EH4: 5 | EI4: Yellow | EJ4: 2 | EK4: Jerseys | EL4: 5 | EM4: Yellow | EN4: 2 | EO4: Jerseys | EP4: 2 | EQ4: Yellow | ER4: 1 | ES4: Jerseys | ET4: 6 | EV4: Yellow | EW4: 4 | EX4: Jerseys | EY4: 4 | EZ4: Yellow | FA4: 2 | FB4: Jerseys | FC4: 5 | FD4: Yellow | FE4: 2 | FF4: Jerseys | FG4: 5 | FH4: Yellow | FI4: 2 | FJ4: Jerseys | FK4: 2
A5: Goals | B5: plus 1 per
Y6: Day 1 | AT6: Day 2 | BO6: Day 3 | CJ6: Day 4 | DE6: Day 5 | DZ6: Day 6 | EU6: Day 7 | FL6: Day 8
A7: LAST | B7: FIRST | C7: Avg Goals/Game | D7: Avg Pts/Gamr | E7: Team | F7: Team Pts | G7: Goals | H7: Total | I7: Team | J7: Team Pts | K7: Goals | L7: Total | M7: Team | N7: Team Pts | O7: Goals | P7: Total | Q7: Team | R7: Team Pts | S7: Goals | T7: Total | U7: Team | V7: Team Pts | W7: Goals | X7: Total | Y7: Total On Day | Z7: Team | AA7: Team Pts | AB7: Goals | AC7: Total | AD7: Team | AE7: Team Pts | AF7: Goals | AG7: Total | AH7: Team | AI7: Team Pts | AJ7: Goals | AK7: Total | AL7: Team | AM7: Team Pts | AN7: Goals | AO7: Total | AP7: Team | AQ7: Team Pts | AR7: Goals | AS7: Total | AT7: Total On Day | AU7: Team | AV7: Team Pts | AW7: Goals | AX7: Total | AY7: Team | AZ7: Team Pts | BA7: Goals | BB7: Total | BC7: Team | BD7: Team Pts | BE7: Goals | BF7: Total | BG7: Team | BH7: Team Pts | BI7: Goals | BJ7: Total | BK7: Team | BL7: Team Pts | BM7: Goals | BN7: Total | BO7: Total On Day | BP7: Team | BQ7: Team Pts | BR7: Goals | BS7: Total | BT7: Team | BU7: Team Pts | BV7: Goals | BW7: Total | BX7: Team | BY7: Team Pts | BZ7: Goals | CA7: Total | CB7: Team | CC7: Team Pts | CD7: Goals | CE7: Total | CF7: Team | CG7: Team Pts | CH7: Goals | CI7: Total | CJ7: Total On Day | CK7: Team | CL7: Team Pts | CM7: Goals | CN7: Total | CO7: Team | CP7: Team Pts | CQ7: Goals | CR7: Total | CS7: Team | CT7: Team Pts | CU7: Goals | CV7: Total | CW7: Team | CX7: Team Pts | CY7: Goals | CZ7: Total | DA7: Team | DB7: Team Pts | DC7: Goals | DD7: Total | DE7: Total On Day | DF7: Team | DG7: Team Pts | DH7: Goals | DI7: Total | DJ7: Team | DK7: Team Pts | DL7: Goals | DM7: Total | DN7: Team | DO7: Team Pts | DP7: Goals | DQ7: Total | DR7: Team | DS7: Team Pts | DT7: Goals | DU7: Total | DV7: Team | DW7: Team Pts | DX7: Goals | DY7: Total | DZ7: Total On Day | EA7: Team | EB7: Team Pts | EC7: Goals | ED7: Total | EE7: Team | EF7: Team Pts | EG7: Goals | EH7: Total | EI7: Team | EJ7: Team Pts | EK7: Goals | EL7: Total | EM7: Team | EN7: Team Pts | EO7: Goals | EP7: Total | EQ7: Team | ER7: Team Pts | ES7: Goals | ET7: Total | EU7: Total On Day | EV7: Team | EW7: Team Pts | EX7: Goals | EY7: Total | EZ7: Team | FA7: Team Pts | FB7: Goals | FC7: Total | FD7: Team | FE7: Team Pts | FF7: Goals | FG7: Total | FH7: Team | FI7: Team Pts | FJ7: Goals | FK7: Total | FL7: Total On Day
A8: Barnhart | B8: Elly | C8: =AVERAGEIF($7:$7,"Goals",8:8) -> 0.24242424 | D8: =VALUE(AVERAGEIF($E$7:$ZZ$7,"Team Pts",$E8:$ZZ8)) -> 1.5151515 | E8: Pink | F8: =IF(OR(H$3="", H$4=""),"", IF(E8=E$3, IF(F$3=H$3, B$3, IF(F$3>H$3, B$2, B$4)), IF(E8=G$3, IF(H$3=F$3, B$3, IF(H$3>F$3, B$2, B$4)), IF(E8=E$4, IF(F$4=H$4, B$3, IF(F$4>H$4, B$2, B$4)), IF(E8=G$4, IF(H$4=F$4, B$3, IF(H$4>F$4, B$2, B$4)), ""))))) -> 0 | G8: 1 | H8: =SUM(F8,G8) -> 1 | I8: Pink | J8: =IF(OR(L$3="", L$4=""),"", IF(I8=I$3, IF(J$3=L$3, B$3, IF(J$3>L$3, B$2, B$4)), IF(I8=K$3, IF(L$3=J$3, B$3, IF(L$3>J$3, B$2, B$4)), IF(I8=I$4, IF(J$4=L$4, B$3, IF(J$4>L$4, B$2, B$4)), IF(I8=K$4, IF(L$4=J$4, B$3, IF(L$4>J$4, B$2, B$4)), ""))))) -> 0 | K8: 0 | L8: =SUM(J8,K8) -> 0 | M8: Pink | N8: =IF(OR(P$3="", P$4=""),"", IF(M8=M$3, IF(N$3=P$3, B$3, IF(N$3>P$3, B$2, B$4)), IF(M8=O$3, IF(P$3=N$3, B$3, IF(P$3>N$3, B$2, B$4)), IF(M8=M$4, IF(N$4=P$4, B$3, IF(N$4>P$4, B$2, B$4)), IF(M8=O$4, IF(P$4=N$4, B$3, IF(P$4>N$4, B$2, B$4)), ""))))) -> 0 | O8: 0 | P8: =SUM(N8,O8) -> 0 | Q8: Jerseys | R8: =IF(OR(T$3="", T$4=""),"", IF(Q8=Q$3, IF(R$3=T$3, B$3, IF(R$3>T$3, B$2, B$4)), IF(Q8=S$3, IF(T$3=R$3, B$3, IF(T$3>R$3, B$2, B$4)), IF(Q8=Q$4, IF(R$4=T$4, B$3, IF(R$4>T$4, B$2, B$4)), IF(Q8=S$4, IF(T$4=R$4, B$3, IF(T$4>R$4, B$2, B$4)), ""))))) -> 3 | S8: 0 | T8: =SUM(R8,S8) -> 3 | U8: Blue | V8: =IF(OR(X$3="", X$4=""),"", IF(U8=U$3, IF(V$3=X$3, B$3, IF(V$3>X$3, B$2, B$4)), IF(U8=W$3, IF(X$3=V$3, B$3, IF(X$3>V$3, B$2, B$4)), IF(U8=U$4, IF(V$4=X$4, B$3, IF(V$4>X$4, B$2, B$4)), IF(U8=W$4, IF(X$4=V$4, B$3, IF(X$4>V$4, B$2, B$4)), ""))))) -> 0 | W8: 0 | X8: =SUM(V8,W8) -> 0 | Y8: =SUM(H8,L8,P8,T8,X8) -> 4 | Z8: Blue | AA8: =IF(Z8="Out", VALUE($D8), IF(OR(AC$3="", AC$4=""),"", IF(Z8=Z$3, IF(AA$3=AC$3, $B$3, IF(AA$3>AC$3, $B$2, $B$4)), IF(Z8=AB$3, IF(AC$3=AA$3, $B$3, IF(AC$3>AA$3, $B$2, $B$4)), IF(Z8=Z$4, IF(AA$4=AC$4, $B$3, IF(AA$4>AC$4, $B$2, $B$4)), IF(Z8=AB$4, IF(AC$4=AA$4, $B$3, IF(AC$4>AA$4, $B$2, $B$4)), "")))))) -> 3 | AB8: 0 | AC8: =SUM(AA8,AB8) -> 3 | AD8: Jerseys | AE8: =IF(AD8="Out", VALUE($D8), IF(OR(AG$3="", AG$4=""),"", IF(AD8=AD$3, IF(AE$3=AG$3, $B$3, IF(AE$3>AG$3, $B$2, $B$4)), IF(AD8=AF$3, IF(AG$3=AE$3, $B$3, IF(AG$3>AE$3, $B$2, $B$4)), IF(AD8=AD$4, IF(AE$4=AG$4, $B$3, IF(AE$4>AG$4, $B$2, $B$4)), IF(AD8=AF$4, IF(AG$4=AE$4, $B$3, IF(AG$4>AE$4, $B$2, $B$4)), "")))))) -> 3 | AF8: 0 | AG8: =SUM(AE8,AF8) -> 3 | AH8: Pink | AI8: =IF(OR(AK$3="", AK$4=""),"", IF(AH8=AH$3, IF(AI$3=AK$3, $B$3, IF(AI$3>AK$3, $B$2, $B$4)), IF(AH8=AJ$3, IF(AK$3=AI$3, $B$3, IF(AK$3>AI$3, $B$2, $B$4)), IF(AH8=AH$4, IF(AI$4=AK$4, $B$3, IF(AI$4>AK$4, $B$2, $B$4)), IF(AH8=AJ$4, IF(AK$4=AI$4, $B$3, IF(AK$4>AI$4, $B$2, $B$4)), ""))))) -> 1 | AJ8: 0 | AK8: =SUM(AI8,AJ8) -> 1 | AL8: Yellow | AM8: =IF(OR(AO$3="", AO$4=""),"", IF(AL8=AL$3, IF(AM$3=AO$3, $B$3, IF(AM$3>AO$3, $B$2, $B$4)), IF(AL8=AN$3, IF(AO$3=AM$3, $B$3, IF(AO$3>AM$3, $B$2, $B$4)), IF(AL8=AL$4, IF(AM$4=AO$4, $B$3, IF(AM$4>AO$4, $B$2, $B$4)), IF(AL8=AN$4, IF(AO$4=AM$4, $B$3, IF(AO$4>AM$4, $B$2, $B$4)), ""))))) -> 1 | AN8: 0 | AO8: =SUM(AM8,AN8) -> 1 | AP8: Out | AQ8: =IF(AP8="Out", VALUE($D8), IF(OR(AS$3="", AS$4=""),"", IF(AP8=AP$3, IF(AQ$3=AS$3, $B$3, IF(AQ$3>AS$3, $B$2, $B$4)), IF(AP8=AR$3, IF(AS$3=AQ$3, $B$3, IF(AS$3>AQ$3, $B$2, $B$4)), IF(AP8=AP$4, IF(AQ$4=AS$4, $B$3, IF(AQ$4>AS$4, $B$2, $B$4)), IF(AP8=AR$4, IF(AS$4=AQ$4, $B$3, IF(AS$4>AQ$4, $B$2, $B$4)), "")))))) -> 1.5151515 | AR8: =IF(AP8="Out", $C8) -> 0.24242424 | AS8: =SUM(AQ8,AR8) -> 1.7575758 | AT8: =SUM(AC8,AG8,AK8,AO8,AS8) -> 9.7575758 | AU8: Jerseys | AV8: =IF(AU8="Out", VALUE($D8), IF(OR(AX$3="", AX$4=""),"", IF(AU8=AU$3, IF(AV$3=AX$3, $B$3, IF(AV$3>AX$3, $B$2, $B$4)), IF(AU8=AW$3, IF(AX$3=AV$3, $B$3, IF(AX$3>AV$3, $B$2, $B$4)), IF(AU8=AU$4, IF(AV$4=AX$4, $B$3, IF(AV$4>AX$4, $B$2, $B$4)), IF(AU8=AW$4, IF(AX$4=AV$4, $B$3, IF(AX$4>AV$4, $B$2, $B$4)), "")))))) -> 0 | AW8: 1 | AX8: =SUM(AV8,AW8) -> 1 | AY8: Pink | AZ8: =IF(AY8="Out", VALUE($D8), IF(OR(BB$3="", BB$4=""),"", IF(AY8=AY$3, IF(AZ$3=BB$3, $B$3, IF(AZ$3>BB$3, $B$2, $B$4)), IF(AY8=BA$3, IF(BB$3=AZ$3, $B$3, IF(BB$3>AZ$3, $B$2, $B$4)), IF(AY8=AY$4, IF(AZ$4=BB$4, $B$3, IF(AZ$4>BB$4, $B$2, $B$4)), IF(AY8=BA$4, IF(BB$4=AZ$4, $B$3, IF(BB$4>AZ$4, $B$2, $B$4)), "")))))) -> 1 | BA8: 0 | BB8: =SUM(AZ8,BA8) -> 1 | BC8: Yellow | BD8: =IF(BC8="Out", VALUE($D8), IF(OR(BF$3="", BF$4=""),"", IF(BC8=BC$3, IF(BD$3=BF$3, $B$3, IF(BD$3>BF$3, $B$2, $B$4)), IF(BC8=BE$3, IF(BF$3=BD$3, $B$3, IF(BF$3>BD$3, $B$2, $B$4)), IF(BC8=BC$4, IF(BD$4=BF$4, $B$3, IF(BD$4>BF$4, $B$2, $B$4)), IF(BC8=BE$4, IF(BF$4=BD$4, $B$3, IF(BF$4>BD$4, $B$2, $B$4)), "")))))) -> 1 | BE8: 0 | BF8: =SUM(BD8,BE8) -> 1 | BG8: Blue | BH8: =IF(BG8="Out", VALUE($D8), IF(OR(BJ$3="", BJ$4=""),"", IF(BG8=BG$3, IF(BH$3=BJ$3, $B$3, IF(BH$3>BJ$3, $B$2, $B$4)), IF(BG8=BI$3, IF(BJ$3=BH$3, $B$3, IF(BJ$3>BH$3, $B$2, $B$4)), IF(BG8=BG$4, IF(BH$4=BJ$4, $B$3, IF(BH$4>BJ$4, $B$2, $B$4)), IF(BG8=BI$4, IF(BJ$4=BH$4, $B$3, IF(BJ$4>BH$4, $B$2, $B$4)), "")))))) -> 0 | BI8: 0 | BJ8: =SUM(BH8,BI8) -> 0 | BK8: Blue | BL8: =IF(BK8="Out", VALUE($D8), IF(OR(BN$3="", BN$4=""),"", IF(BK8=BK$3, IF(BL$3=BN$3, $B$3, IF(BL$3>BN$3, $B$2, $B$4)), IF(BK8=BM$3, IF(BN$3=BL$3, $B$3, IF(BN$3>BL$3, $B$2, $B$4)), IF(BK8=BK$4, IF(BL$4=BN$4, $B$3, IF(BL$4>BN$4, $B$2, $B$4)), IF(BK8=BM$4, IF(BN$4=BL$4, $B$3, IF(BN$4>BL$4, $B$2, $B$4)), "")))))) -> 0 | BM8: 0 | BN8: =SUM(BL8,BM8) -> 0 | BO8: =SUM(AX8,BB8,BF8,BJ8,BN8) -> 3 | BP8: Jerseys | BQ8: =IF(BP8="Out", VALUE($D8), IF(OR(BS$3="", BS$4=""),"", IF(BP8=BP$3, IF(BQ$3=BS$3, $B$3, IF(BQ$3>BS$3, $B$2, $B$4)), IF(BP8=BR$3, IF(BS$3=BQ$3, $B$3, IF(BS$3>BQ$3, $B$2, $B$4)), IF(BP8=BP$4, IF(BQ$4=BS$4, $B$3, IF(BQ$4>BS$4, $B$2, $B$4)), IF(BP8=BR$4, IF(BS$4=BQ$4, $B$3, IF(BS$4>BQ$4, $B$2, $B$4)), "")))))) -> 0 | BR8: 0 | BS8: =SUM(BQ8,BR8) -> 0 | BT8: Pink | BU8: =IF(BT8="Out", VALUE($D8), IF(OR(BW$3="", BW$4=""),"", IF(BT8=BT$3, IF(BU$3=BW$3, $B$3, IF(BU$3>BW$3, $B$2, $B$4)), IF(BT8=BV$3, IF(BW$3=BU$3, $B$3, IF(BW$3>BU$3, $B$2, $B$4)), IF(BT8=BT$4, IF(BU$4=BW$4, $B$3, IF(BU$4>BW$4, $B$2, $B$4)), IF(BT8=BV$4, IF(BW$4=BU$4, $B$3, IF(BW$4>BU$4, $B$2, $B$4)), "")))))) -> 3 | BV8: 0 | BW8: =SUM(BU8,BV8) -> 3 | BX8: Jerseys | BY8: =IF(BX8="Out", VALUE($D8), IF(OR(CA$3="", CA$4=""),"", IF(BX8=BX$3, IF(BY$3=CA$3, $B$3, IF(BY$3>CA$3, $B$2, $B$4)), IF(BX8=BZ$3, IF(CA$3=BY$3, $B$3, IF(CA$3>BY$3, $B$2, $B$4)), IF(BX8=BX$4, IF(BY$4=CA$4, $B$3, IF(BY$4>CA$4, $B$2, $B$4)), IF(BX8=BZ$4, IF(CA$4=BY$4, $B$3, IF(CA$4>BY$4, $B$2, $B$4)), "")))))) -> 3 | BZ8: 1 | CA8: =SUM(BY8,BZ8) -> 4 | CB8: Blue | CC8: =IF(CB8="Out", VALUE($D8), IF(OR(CE$3="", CE$4=""),"", IF(CB8=CB$3, IF(CC$3=CE$3, $B$3, IF(CC$3>CE$3, $B$2, $B$4)), IF(CB8=CD$3, IF(CE$3=CC$3, $B$3, IF(CE$3>CC$3, $B$2, $B$4)), IF(CB8=CB$4, IF(CC$4=CE$4, $B$3, IF(CC$4>CE$4, $B$2, $B$4)), IF(CB8=CD$4, IF(CE$4=CC$4, $B$3, IF(CE$4>CC$4, $B$2, $B$4)), "")))))) -> 0 | CD8: 1 | CE8: =SUM(CC8,CD8) -> 1 | CF8: Jerseys | CG8: =IF(CF8="Out", VALUE($D8), IF(OR(CI$3="", CI$4=""),"", IF(CF8=CF$3, IF(CG$3=CI$3, $B$3, IF(CG$3>CI$3, $B$2, $B$4)), IF(CF8=CH$3, IF(CI$3=CG$3, $B$3, IF(CI$3>CG$3, $B$2, $B$4)), IF(CF8=CF$4, IF(CG$4=CI$4, $B$3, IF(CG$4>CI$4, $B$2, $B$4)), IF(CF8=CH$4, IF(CI$4=CG$4, $B$3, IF(CI$4>CG$4, $B$2, $B$4)), "")))))) -> 3 | CH8: 1 | CI8: =SUM(CG8,CH8) -> 4 | CJ8: =SUM(BS8,BW8,CA8,CE8,CI8) -> 12 | CK8: Out | CL8: =IF(CK8="Out", VALUE($D8), IF(OR(CN$3="", CN$4=""),"", IF(CK8=CK$3, IF(CL$3=CN$3, $B$3, IF(CL$3>CN$3, $B$2, $B$4)), IF(CK8=CM$3, IF(CN$3=CL$3, $B$3, IF(CN$3>CL$3, $B$2, $B$4)), IF(CK8=CK$4, IF(CL$4=CN$4, $B$3, IF(CL$4>CN$4, $B$2, $B$4)), IF(CK8=CM$4, IF(CN$4=CL$4, $B$3, IF(CN$4>CL$4, $B$2, $B$4)), "")))))) -> 1.5151515 | CM8: =IF(CK8="Out", $C8) -> 0.24242424 | CN8: =SUM(CL8,CM8) -> 1.7575758 | CO8: Out | CP8: =IF(CO8="Out", VALUE($D8), IF(OR(CR$3="", CR$4=""),"", IF(CO8=CO$3, IF(CP$3=CR$3, $B$3, IF(CP$3>CR$3, $B$2, $B$4)), IF(CO8=CQ$3, IF(CR$3=CP$3, $B$3, IF(CR$3>CP$3, $B$2, $B$4)), IF(CO8=CO$4, IF(CP$4=CR$4, $B$3, IF(CP$4>CR$4, $B$2, $B$4)), IF(CO8=CQ$4, IF(CR$4=CP$4, $B$3, IF(CR$4>CP$4, $B$2, $B$4)), "")))))) -> 1.5151515 | CQ8: =IF(CO8="Out", $C8) -> 0.24242424 | CR8: =SUM(CP8,CQ8) -> 1.7575758 | CS8: Out | CT8: =IF(CS8="Out", VALUE($D8), IF(OR(CV$3="", CV$4=""),"", IF(CS8=CS$3, IF(CT$3=CV$3, $B$3, IF(CT$3>CV$3, $B$2, $B$4)), IF(CS8=CU$3, IF(CV$3=CT$3, $B$3, IF(CV$3>CT$3, $B$2, $B$4)), IF(CS8=CS$4, IF(CT$4=CV$4, $B$3, IF(CT$4>CV$4, $B$2, $B$4)), IF(CS8=CU$4, IF(CV$4=CT$4, $B$3, IF(CV$4>CT$4, $B$2, $B$4)), "")))))) -> 1.5151515 | CU8: =IF(CS8="Out", $C8) -> 0.24242424 | CV8: =SUM(CT8,CU8) -> 1.7575758 | CW8: Out | CX8: =IF(CW8="Out", VALUE($D8), IF(OR(CZ$3="", CZ$4=""),"", IF(CW8=CW$3, IF(CX$3=CZ$3, $B$3, IF(CX$3>CZ$3, $B$2, $B$4)), IF(CW8=CY$3, IF(CZ$3=CX$3, $B$3, IF(CZ$3>CX$3, $B$2, $B$4)), IF(CW8=CW$4, IF(CX$4=CZ$4, $B$3, IF(CX$4>CZ$4, $B$2, $B$4)), IF(CW8=CY$4, IF(CZ$4=CX$4, $B$3, IF(CZ$4>CX$4, $B$2, $B$4)), "")))))) -> 1.5151515 | CY8: =IF(CW8="Out", $C8) -> 0.24242424 | CZ8: =SUM(CX8,CY8) -> 1.7575758 | DA8: Out | DB8: =IF(DA8="Out", VALUE($D8), IF(OR(DD$3="", DD$4=""),"", IF(DA8=DA$3, IF(DB$3=DD$3, $B$3, IF(DB$3>DD$3, $B$2, $B$4)), IF(DA8=DC$3, IF(DD$3=DB$3, $B$3, IF(DD$3>DB$3, $B$2, $B$4)), IF(DA8=DA$4, IF(DB$4=DD$4, $B$3, IF(DB$4>DD$4, $B$2, $B$4)), IF(DA8=DC$4, IF(DD$4=DB$4, $B$3, IF(DD$4>DB$4, $B$2, $B$4)), "")))))) -> 1.5151515 | DC8: =IF(DA8="Out", $C8) -> 0.24242424 | DD8: =SUM(DB8,DC8) -> 1.7575758 | DE8: =SUM(CN8,CR8,CV8,CZ8,DD8) -> 8.7878788 | DF8: Blue | DG8: =IF(DF8="Out", VALUE($D8), IF(OR(DI$3="", DI$4=""),"", IF(DF8=DF$3, IF(DG$3=DI$3, $B$3, IF(DG$3>DI$3, $B$2, $B$4)), IF(DF8=DH$3, IF(DI$3=DG$3, $B$3, IF(DI$3>DG$3, $B$2, $B$4)), IF(DF8=DF$4, IF(DG$4=DI$4, $B$3, IF(DG$4>DI$4, $B$2, $B$4)), IF(DF8=DH$4, IF(DI$4=DG$4, $B$3, IF(DI$4>DG$4, $B$2, $B$4)), "")))))) -> 3 | DH8: 0 | DI8: =SUM(DG8,DH8) -> 3 | DJ8: Pink | DK8: =IF(DJ8="Out", VALUE($D8), IF(OR(DM$3="", DM$4=""),"", IF(DJ8=DJ$3, IF(DK$3=DM$3, $B$3, IF(DK$3>DM$3, $B$2, $B$4)), IF(DJ8=DL$3, IF(DM$3=DK$3, $B$3, IF(DM$3>DK$3, $B$2, $B$4)), IF(DJ8=DJ$4, IF(DK$4=DM$4, $B$3, IF(DK$4>DM$4, $B$2, $B$4)), IF(DJ8=DL$4, IF(DM$4=DK$4, $B$3, IF(DM$4>DK$4, $B$2, $B$4)), "")))))) -> 3 | DL8: 1 | DM8: =SUM(DK8,DL8) -> 4 | DN8: Yellow | DO8: =IF(DN8="Out", VALUE($D8), IF(OR(DQ$3="", DQ$4=""),"", IF(DN8=DN$3, IF(DO$3=DQ$3, $B$3, IF(DO$3>DQ$3, $B$2, $B$4)), IF(DN8=DP$3, IF(DQ$3=DO$3, $B$3, IF(DQ$3>DO$3, $B$2, $B$4)), IF(DN8=DN$4, IF(DO$4=DQ$4, $B$3, IF(DO$4>DQ$4, $B$2, $B$4)), IF(DN8=DP$4, IF(DQ$4=DO$4, $B$3, IF(DQ$4>DO$4, $B$2, $B$4)), "")))))) -> 3 | DP8: 0 | DQ8: =SUM(DO8,DP8) -> 3 | DR8: Pink | DS8: =IF(DR8="Out", VALUE($D8), IF(OR(DU$3="", DU$4=""),"", IF(DR8=DR$3, IF(DS$3=DU$3, $B$3, IF(DS$3>DU$3, $B$2, $B$4)), IF(DR8=DT$3, IF(DU$3=DS$3, $B$3, IF(DU$3>DS$3, $B$2, $B$4)), IF(DR8=DR$4, IF(DS$4=DU$4, $B$3, IF(DS$4>DU$4, $B$2, $B$4)), IF(DR8=DT$4, IF(DU$4=DS$4, $B$3, IF(DU$4>DS$4, $B$2, $B$4)), "")))))) -> 3 | DT8: 0 | DU8: =SUM(DS8,DT8) -> 3 | DV8: Yellow | DW8: =IF(DV8="Out", VALUE($D8), IF(OR(DY$3="", DY$4=""),"", IF(DV8=DV$3, IF(DW$3=DY$3, $B$3, IF(DW$3>DY$3, $B$2, $B$4)), IF(DV8=DX$3, IF(DY$3=DW$3, $B$3, IF(DY$3>DW$3, $B$2, $B$4)), IF(DV8=DV$4, IF(DW$4=DY$4, $B$3, IF(DW$4>DY$4, $B$2, $B$4)), IF(DV8=DX$4, IF(DY$4=DW$4, $B$3, IF(DY$4>DW$4, $B$2, $B$4)), "")))))) -> 3 | DX8: 0 | DY8: =SUM(DW8,DX8) -> 3 | DZ8: =SUM(DI8,DM8,DQ8,DU8,DY8) -> 16 | EA8: Jerseys | EB8: =IF(EA8="Out", VALUE($D8), IF(OR(ED$3="", ED$4=""),"", IF(EA8=EA$3, IF(EB$3=ED$3, $B$3, IF(EB$3>ED$3, $B$2, $B$4)), IF(EA8=EC$3, IF(ED$3=EB$3, $B$3, IF(ED$3>EB$3, $B$2, $B$4)), IF(EA8=EA$4, IF(EB$4=ED$4, $B$3, IF(EB$4>ED$4, $B$2, $B$4)), IF(EA8=EC$4, IF(ED$4=EB$4, $B$3, IF(ED$4>EB$4, $B$2, $B$4)), "")))))) -> 1 | EC8: 0 | ED8: =SUM(EB8,EC8) -> 1 | EE8: Pink | EF8: =IF(EE8="Out", VALUE($D8), IF(OR(EH$3="", EH$4=""),"", IF(EE8=EE$3, IF(EF$3=EH$3, $B$3, IF(EF$3>EH$3, $B$2, $B$4)), IF(EE8=EG$3, IF(EH$3=EF$3, $B$3, IF(EH$3>EF$3, $B$2, $B$4)), IF(EE8=EE$4, IF(EF$4=EH$4, $B$3, IF(EF$4>EH$4, $B$2, $B$4)), IF(EE8=EG$4, IF(EH$4=EF$4, $B$3, IF(EH$4>EF$4, $B$2, $B$4)), "")))))) -> 3 | EG8: 0 | EH8: =SUM(EF8,EG8) -> 3 | EI8: Blue | EJ8: =IF(EI8="Out", VALUE($D8), IF(OR(EL$3="", EL$4=""),"", IF(EI8=EI$3, IF(EJ$3=EL$3, $B$3, IF(EJ$3>EL$3, $B$2, $B$4)), IF(EI8=EK$3, IF(EL$3=EJ$3, $B$3, IF(EL$3>EJ$3, $B$2, $B$4)), IF(EI8=EI$4, IF(EJ$4=EL$4, $B$3, IF(EJ$4>EL$4, $B$2, $B$4)), IF(EI8=EK$4, IF(EL$4=EJ$4, $B$3, IF(EL$4>EJ$4, $B$2, $B$4)), "")))))) -> 0 | EK8: 0 | EL8: =SUM(EJ8,EK8) -> 0 | EM8: Pink | EN8: =IF(EM8="Out", VALUE($D8), IF(OR(EP$3="", EP$4=""),"", IF(EM8=EM$3, IF(EN$3=EP$3, $B$3, IF(EN$3>EP$3, $B$2, $B$4)), IF(EM8=EO$3, IF(EP$3=EN$3, $B$3, IF(EP$3>EN$3, $B$2, $B$4)), IF(EM8=EM$4, IF(EN$4=EP$4, $B$3, IF(EN$4>EP$4, $B$2, $B$4)), IF(EM8=EO$4, IF(EP$4=EN$4, $B$3, IF(EP$4>EN$4, $B$2, $B$4)), "")))))) -> 0 | EO8: 0 | EP8: =SUM(EN8,EO8) -> 0 | EQ8: Jerseys | ER8: =IF(EQ8="Out", VALUE($D8), IF(OR(ET$3="", ET$4=""),"", IF(EQ8=EQ$3, IF(ER$3=ET$3, $B$3, IF(ER$3>ET$3, $B$2, $B$4)), IF(EQ8=ES$3, IF(ET$3=ER$3, $B$3, IF(ET$3>ER$3, $B$2, $B$4)), IF(EQ8=EQ$4, IF(ER$4=ET$4, $B$3, IF(ER$4>ET$4, $B$2, $B$4)), IF(EQ8=ES$4, IF(ET$4=ER$4, $B$3, IF(ET$4>ER$4, $B$2, $B$4)), "")))))) -> 3 | ES8: 1 | ET8: =SUM(ER8,ES8) -> 4 | EU8: =SUM(ED8,EH8,EL8,EP8,ET8) -> 8 | EV8: Blue | EW8: =IF(EV8="Out", VALUE($D8), IF(OR(EY$3="", EY$4=""),"", IF(EV8=EV$3, IF(EW$3=EY$3, $B$3, IF(EW$3>EY$3, $B$2, $B$4)), IF(EV8=EX$3, IF(EY$3=EW$3, $B$3, IF(EY$3>EW$3, $B$2, $B$4)), IF(EV8=EV$4, IF(EW$4=EY$4, $B$3, IF(EW$4>EY$4, $B$2, $B$4)), IF(EV8=EX$4, IF(EY$4=EW$4, $B$3, IF(EY$4>EW$4, $B$2, $B$4)), "")))))) -> 3 | EX8: 0 | EY8: =SUM(EW8,EX8) -> 3 | EZ8: Blue | FA8: =IF(EZ8="Out", VALUE($D8), IF(OR(FC$3="", FC$4=""),"", IF(EZ8=EZ$3, IF(FA$3=FC$3, $B$3, IF(FA$3>FC$3, $B$2, $B$4)), IF(EZ8=FB$3, IF(FC$3=FA$3, $B$3, IF(FC$3>FA$3, $B$2, $B$4)), IF(EZ8=EZ$4, IF(FA$4=FC$4, $B$3, IF(FA$4>FC$4, $B$2, $B$4)), IF(EZ8=FB$4, IF(FC$4=FA$4, $B$3, IF(FC$4>FA$4, $B$2, $B$4)), "")))))) -> 0 | FB8: 0 | FC8: =SUM(FA8,FB8) -> 0 | FD8: Yellow | FE8: =IF(FD8="Out", VALUE($D8), IF(OR(FG$3="", FG$4=""),"", IF(FD8=FD$3, IF(FE$3=FG$3, $B$3, IF(FE$3>FG$3, $B$2, $B$4)), IF(FD8=FF$3, IF(FG$3=FE$3, $B$3, IF(FG$3>FE$3, $B$2, $B$4)), IF(FD8=FD$4, IF(FE$4=FG$4, $B$3, IF(FE$4>FG$4, $B$2, $B$4)), IF(FD8=FF$4, IF(FG$4=FE$4, $B$3, IF(FG$4>FE$4, $B$2, $B$4)), "")))))) -> 0 | FF8: 0 | FG8: =SUM(FE8,FF8) -> 0 | FH8: Blue | FI8: =IF(FH8="Out", VALUE($D8), IF(OR(FK$3="", FK$4=""),"", IF(FH8=FH$3, IF(FI$3=FK$3, $B$3, IF(FI$3>FK$3, $B$2, $B$4)), IF(FH8=FJ$3, IF(FK$3=FI$3, $B$3, IF(FK$3>FI$3, $B$2, $B$4)), IF(FH8=FH$4, IF(FI$4=FK$4, $B$3, IF(FI$4>FK$4, $B$2, $B$4)), IF(FH8=FJ$4, IF(FK$4=FI$4, $B$3, IF(FK$4>FI$4, $B$2, $B$4)), "")))))) -> 3 | FJ8: 1 | FK8: =SUM(FI8,FJ8) -> 4 | FL8: =SUM(EU8,EY8,FC8,FG8,FK8) -> 15
A9: Bieger | B9: Mackenzie | C9: =AVERAGEIF($7:$7,"Goals",9:9) -> 0.36363636 | D9: =VALUE(AVERAGEIF($E$7:$ZZ$7,"Team Pts",$E9:$ZZ9)) -> 1.5454545 | E9: Pink | F9: =IF(OR(H$3="", H$4=""),"", IF(E9=E$3, IF(F$3=H$3, B$3, IF(F$3>H$3, B$2, B$4)), IF(E9=G$3, IF(H$3=F$3, B$3, IF(H$3>F$3, B$2, B$4)), IF(E9=E$4, IF(F$4=H$4, B$3, IF(F$4>H$4, B$2, B$4)), IF(E9=G$4, IF(H$4=F$4, B$3, IF(H$4>F$4, B$2, B$4)), ""))))) -> 0 | G9: 0 | H9: =SUM(F9,G9) -> 0 | I9: Pink | J9: =IF(OR(L$3="", L$4=""),"", IF(I9=I$3, IF(J$3=L$3, B$3, IF(J$3>L$3, B$2, B$4)), IF(I9=K$3, IF(L$3=J$3, B$3, IF(L$3>J$3, B$2, B$4)), IF(I9=I$4, IF(J$4=L$4, B$3, IF(J$4>L$4, B$2, B$4)), IF(I9=K$4, IF(L$4=J$4, B$3, IF(L$4>J$4, B$2, B$4)), ""))))) -> 0 | K9: 0 | L9: =SUM(J9,K9) -> 0 | M9: Blue | N9: =IF(OR(P$3="", P$4=""),"", IF(M9=M$3, IF(N$3=P$3, B$3, IF(N$3>P$3, B$2, B$4)), IF(M9=O$3, IF(P$3=N$3, B$3, IF(P$3>N$3, B$2, B$4)), IF(M9=M$4, IF(N$4=P$4, B$3, IF(N$4>P$4, B$2, B$4)), IF(M9=O$4, IF(P$4=N$4, B$3, IF(P$4>N$4, B$2, B$4)), ""))))) -> 3 | O9: 1 | P9: =SUM(N9,O9) -> 4 | Q9: Blue | R9: =IF(OR(T$3="", T$4=""),"", IF(Q9=Q$3, IF(R$3=T$3, B$3, IF(R$3>T$3, B$2, B$4)), IF(Q9=S$3, IF(T$3=R$3, B$3, IF(T$3>R$3, B$2, B$4)), IF(Q9=Q$4, IF(R$4=T$4, B$3, IF(R$4>T$4, B$2, B$4)), IF(Q9=S$4, IF(T$4=R$4, B$3, IF(T$4>R$4, B$2, B$4)), ""))))) -> 3 | S9: 0 | T9: =SUM(R9,S9) -> 3 | U9: Jerseys | V9: =IF(OR(X$3="", X$4=""),"", IF(U9=U$3, IF(V$3=X$3, B$3, IF(V$3>X$3, B$2, B$4)), IF(U9=W$3, IF(X$3=V$3, B$3, IF(X$3>V$3, B$2, B$4)), IF(U9=U$4, IF(V$4=X$4, B$3, IF(V$4>X$4, B$2, B$4)), IF(U9=W$4, IF(X$4=V$4, B$3, IF(X$4>V$4, B$2, B$4)), ""))))) -> 0 | W9: 0 | X9: =SUM(V9,W9) -> 0 | Y9: =SUM(H9,L9,P9,T9,X9) -> 7 | Z9: Out | AA9: =IF(Z9="Out", D9, IF(OR(AC$3="", AC$4=""),"", IF(Z9=Z$3, IF(AA$3=AC$3, $B$3, IF(AA$3>AC$3, $B$2, $B$4)), IF(Z9=AB$3, IF(AC$3=AA$3, $B$3, IF(AC$3>AA$3, $B$2, $B$4)), IF(Z9=Z$4, IF(AA$4=AC$4, $B$3, IF(AA$4>AC$4, $B$2, $B$4)), IF(Z9=AB$4, IF(AC$4=AA$4, $B$3, IF(AC$4>AA$4, $B$2, $B$4)), "")))))) -> 1.5454545 | AB9: =IF(Z9="Out", $C9) -> 0.36363636 | AC9: =SUM(AA9,AB9) -> 1.9090909 | AD9: Jerseys | AE9: =IF(AD9="Out", VALUE($D9), IF(OR(AG$3="", AG$4=""),"", IF(AD9=AD$3, IF(AE$3=AG$3, $B$3, IF(AE$3>AG$3, $B$2, $B$4)), IF(AD9=AF$3, IF(AG$3=AE$3, $B$3, IF(AG$3>AE$3, $B$2, $B$4)), IF(AD9=AD$4, IF(AE$4=AG$4, $B$3, IF(AE$4>AG$4, $B$2, $B$4)), IF(AD9=AF$4, IF(AG$4=AE$4, $B$3, IF(AG$4>AE$4, $B$2, $B$4)), "")))))) -> 3 | AF9: 0 | AG9: =SUM(AE9,AF9) -> 3 | AH9: Yellow | AI9: =IF(OR(AK$3="", AK$4=""),"", IF(AH9=AH$3, IF(AI$3=AK$3, $B$3, IF(AI$3>AK$3, $B$2, $B$4)), IF(AH9=AJ$3, IF(AK$3=AI$3, $B$3, IF(AK$3>AI$3, $B$2, $B$4)), IF(AH9=AH$4, IF(AI$4=AK$4, $B$3, IF(AI$4>AK$4, $B$2, $B$4)), IF(AH9=AJ$4, IF(AK$4=AI$4, $B$3, IF(AK$4>AI$4, $B$2, $B$4)), ""))))) -> 0 | AJ9: 0 | AK9: =SUM(AI9,AJ9) -> 0 | AL9: Jerseys | AM9: =IF(OR(AO$3="", AO$4=""),"", IF(AL9=AL$3, IF(AM$3=AO$3, $B$3, IF(AM$3>AO$3, $B$2, $B$4)), IF(AL9=AN$3, IF(AO$3=AM$3, $B$3, IF(AO$3>AM$3, $B$2, $B$4)), IF(AL9=AL$4, IF(AM$4=AO$4, $B$3, IF(AM$4>AO$4, $B$2, $B$4)), IF(AL9=AN$4, IF(AO$4=AM$4, $B$3, IF(AO$4>AM$4, $B$2, $B$4)), ""))))) -> 1 | AN9: 0 | AO9: =SUM(AM9,AN9) -> 1 | AP9: Pink | AQ9: =IF(OR(AS$3="", AS$4=""),"", IF(AP9=AP$3, IF(AQ$3=AS$3, $B$3, IF(AQ$3>AS$3, $B$2, $B$4)), IF(AP9=AR$3, IF(AS$3=AQ$3, $B$3, IF(AS$3>AQ$3, $B$2, $B$4)), IF(AP9=AP$4, IF(AQ$4=AS$4, $B$3, IF(AQ$4>AS$4, $B$2, $B$4)), IF(AP9=AR$4, IF(AS$4=AQ$4, $B$3, IF(AS$4>AQ$4, $B$2, $B$4)), ""))))) -> 0 | AR9: 1 | AS9: =SUM(AQ9,AR9) -> 1 | AT9: =SUM(AC9,AG9,AK9,AO9,AS9) -> 6.9090909 | AU9: Blue | AV9: =IF(AU9="Out", VALUE($D9), IF(OR(AX$3="", AX$4=""),"", IF(AU9=AU$3, IF(AV$3=AX$3, $B$3, IF(AV$3>AX$3, $B$2, $B$4)), IF(AU9=AW$3, IF(AX$3=AV$3, $B$3, IF(AX$3>AV$3, $B$2, $B$4)), IF(AU9=AU$4, IF(AV$4=AX$4, $B$3, IF(AV$4>AX$4, $B$2, $B$4)), IF(AU9=AW$4, IF(AX$4=AV$4, $B$3, IF(AX$4>AV$4, $B$2, $B$4)), "")))))) -> 3 | AW9: 0 | AX9: =SUM(AV9,AW9) -> 3 | AY9: Jerseys | AZ9: =IF(AY9="Out", VALUE($D9), IF(OR(BB$3="", BB$4=""),"", IF(AY9=AY$3, IF(AZ$3=BB$3, $B$3, IF(AZ$3>BB$3, $B$2, $B$4)), IF(AY9=BA$3, IF(BB$3=AZ$3, $B$3, IF(BB$3>AZ$3, $B$2, $B$4)), IF(AY9=AY$4, IF(AZ$4=BB$4, $B$3, IF(AZ$4>BB$4, $B$2, $B$4)), IF(AY9=BA$4, IF(BB$4=AZ$4, $B$3, IF(BB$4>AZ$4, $B$2, $B$4)), "")))))) -> 0 | BA9: 0 | BB9: =SUM(AZ9,BA9) -> 0 | BC9: Pink | BD9: =IF(BC9="Out", VALUE($D9), IF(OR(BF$3="", BF$4=""),"", IF(BC9=BC$3, IF(BD$3=BF$3, $B$3, IF(BD$3>BF$3, $B$2, $B$4)), IF(BC9=BE$3, IF(BF$3=BD$3, $B$3, IF(BF$3>BD$3, $B$2, $B$4)), IF(BC9=BC$4, IF(BD$4=BF$4, $B$3, IF(BD$4>BF$4, $B$2, $B$4)), IF(BC9=BE$4, IF(BF$4=BD$4, $B$3, IF(BF$4>BD$4, $B$2, $B$4)), "")))))) -> 3 | BE9: 0 | BF9: =SUM(BD9,BE9) -> 3 | BG9: Blue | BH9: =IF(BG9="Out", VALUE($D9), IF(OR(BJ$3="", BJ$4=""),"", IF(BG9=BG$3, IF(BH$3=BJ$3, $B$3, IF(BH$3>BJ$3, $B$2, $B$4)), IF(BG9=BI$3, IF(BJ$3=BH$3, $B$3, IF(BJ$3>BH$3, $B$2, $B$4)), IF(BG9=BG$4, IF(BH$4=BJ$4, $B$3, IF(BH$4>BJ$4, $B$2, $B$4)), IF(BG9=BI$4, IF(BJ$4=BH$4, $B$3, IF(BJ$4>BH$4, $B$2, $B$4)), "")))))) -> 0 | BI9: 0 | BJ9: =SUM(BH9,BI9) -> 0 | BK9: Jerseys | BL9: =IF(BK9="Out", VALUE($D9), IF(OR(BN$3="", BN$4=""),"", IF(BK9=BK$3, IF(BL$3=BN$3, $B$3, IF(BL$3>BN$3, $B$2, $B$4)), IF(BK9=BM$3, IF(BN$3=BL$3, $B$3, IF(BN$3>BL$3, $B$2, $B$4)), IF(BK9=BK$4, IF(BL$4=BN$4, $B$3, IF(BL$4>BN$4, $B$2, $B$4)), IF(BK9=BM$4, IF(BN$4=BL$4, $B$3, IF(BN$4>BL$4, $B$2, $B$4)), "")))))) -> 3 | BM9: 0 | BN9: =SUM(BL9,BM9) -> 3 | BO9: =SUM(AX9,BB9,BF9,BJ9,BN9) -> 9 | BP9: Out | BQ9: =IF(BP9="Out", VALUE($D9), IF(OR(BS$3="", BS$4=""),"", IF(BP9=BP$3, IF(BQ$3=BS$3, $B$3, IF(BQ$3>BS$3, $B$2, $B$4)), IF(BP9=BR$3, IF(BS$3=BQ$3, $B$3, IF(BS$3>BQ$3, $B$2, $B$4)), IF(BP9=BP$4, IF(BQ$4=BS$4, $B$3, IF(BQ$4>BS$4, $B$2, $B$4)), IF(BP9=BR$4, IF(BS$4=BQ$4, $B$3, IF(BS$4>BQ$4, $B$2, $B$4)), "")))))) -> 1.5454545 | BR9: =IF(BP9="Out", $C9) -> 0.36363636 | BS9: =SUM(BQ9,BR9) -> 1.9090909 | BT9: Out | BU9: =IF(BT9="Out", VALUE($D9), IF(OR(BW$3="", BW$4=""),"", IF(BT9=BT$3, IF(BU$3=BW$3, $B$3, IF(BU$3>BW$3, $B$2, $B$4)), IF(BT9=BV$3, IF(BW$3=BU$3, $B$3, IF(BW$3>BU$3, $B$2, $B$4)), IF(BT9=BT$4, IF(BU$4=BW$4, $B$3, IF(BU$4>BW$4, $B$2, $B$4)), IF(BT9=BV$4, IF(BW$4=BU$4, $B$3, IF(BW$4>BU$4, $B$2, $B$4)), "")))))) -> 1.5454545 | BV9: =IF(BT9="Out", $C9) -> 0.36363636 | BW9: =SUM(BU9,BV9) -> 1.9090909 | BX9: Out | BY9: =IF(BX9="Out", VALUE($D9), IF(OR(CA$3="", CA$4=""),"", IF(BX9=BX$3, IF(BY$3=CA$3, $B$3, IF(BY$3>CA$3, $B$2, $B$4)), IF(BX9=BZ$3, IF(CA$3=BY$3, $B$3, IF(CA$3>BY$3, $B$2, $B$4)), IF(BX9=BX$4, IF(BY$4=CA$4, $B$3, IF(BY$4>CA$4, $B$2, $B$4)), IF(BX9=BZ$4, IF(CA$4=BY$4, $B$3, IF(CA$4>BY$4, $B$2, $B$4)), "")))))) -> 1.5454545 | BZ9: =IF(BX9="Out", $C9) -> 0.36363636 | CA9: =SUM(BY9,BZ9) -> 1.9090909 | CB9: Out | CC9: =IF(CB9="Out", VALUE($D9), IF(OR(CE$3="", CE$4=""),"", IF(CB9=CB$3, IF(CC$3=CE$3, $B$3, IF(CC$3>CE$3, $B$2, $B$4)), IF(CB9=CD$3, IF(CE$3=CC$3, $B$3, IF(CE$3>CC$3, $B$2, $B$4)), IF(CB9=CB$4, IF(CC$4=CE$4, $B$3, IF(CC$4>CE$4, $B$2, $B$4)), IF(CB9=CD$4, IF(CE$4=CC$4, $B$3, IF(CE$4>CC$4, $B$2, $B$4)), "")))))) -> 1.5454545 | CD9: =IF(CB9="Out", $C9) -> 0.36363636 | CE9: =SUM(CC9,CD9) -> 1.9090909 | CF9: Out | CG9: =IF(CF9="Out", VALUE($D9), IF(OR(CI$3="", CI$4=""),"", IF(CF9=CF$3, IF(CG$3=CI$3, $B$3, IF(CG$3>CI$3, $B$2, $B$4)), IF(CF9=CH$3, IF(CI$3=CG$3, $B$3, IF(CI$3>CG$3, $B$2, $B$4)), IF(CF9=CF$4, IF(CG$4=CI$4, $B$3, IF(CG$4>CI$4, $B$2, $B$4)), IF(CF9=CH$4, IF(CI$4=CG$4, $B$3, IF(CI$4>CG$4, $B$2, $B$4)), "")))))) -> 1.5454545 | CH9: =IF(CF9="Out", $C9) -> 0.36363636 | CI9: =SUM(CG9,CH9) -> 1.9090909 | CJ9: =SUM(BS9,BW9,CA9,CE9,CI9) -> 9.5454545 | CK9: Jerseys | CL9: =IF(CK9="Out", VALUE($D9), IF(OR(CN$3="", CN$4=""),"", IF(CK9=CK$3, IF(CL$3=CN$3, $B$3, IF(CL$3>CN$3, $B$2, $B$4)), IF(CK9=CM$3, IF(CN$3=CL$3, $B$3, IF(CN$3>CL$3, $B$2, $B$4)), IF(CK9=CK$4, IF(CL$4=CN$4, $B$3, IF(CL$4>CN$4, $B$2, $B$4)), IF(CK9=CM$4, IF(CN$4=CL$4, $B$3, IF(CN$4>CL$4, $B$2, $B$4)), "")))))) -> 3 | CM9: 0 | CN9: =SUM(CL9,CM9) -> 3 | CO9: Jerseys | CP9: =IF(CO9="Out", VALUE($D9), IF(OR(CR$3="", CR$4=""),"", IF(CO9=CO$3, IF(CP$3=CR$3, $B$3, IF(CP$3>CR$3, $B$2, $B$4)), IF(CO9=CQ$3, IF(CR$3=CP$3, $B$3, IF(CR$3>CP$3, $B$2, $B$4)), IF(CO9=CO$4, IF(CP$4=CR$4, $B$3, IF(CP$4>CR$4, $B$2, $B$4)), IF(CO9=CQ$4, IF(CR$4=CP$4, $B$3, IF(CR$4>CP$4, $B$2, $B$4)), "")))))) -> 3 | CQ9: 0 | CR9: =SUM(CP9,CQ9) -> 3 | CS9: Jerseys | CT9: =IF(CS9="Out", VALUE($D9), IF(OR(CV$3="", CV$4=""),"", IF(CS9=CS$3, IF(CT$3=CV$3, $B$3, IF(CT$3>CV$3, $B$2, $B$4)), IF(CS9=CU$3, IF(CV$3=CT$3, $B$3, IF(CV$3>CT$3, $B$2, $B$4)), IF(CS9=CS$4, IF(CT$4=CV$4, $B$3, IF(CT$4>CV$4, $B$2, $B$4)), IF(CS9=CU$4, IF(CV$4=CT$4, $B$3, IF(CV$4>CT$4, $B$2, $B$4)), "")))))) -> 3 | CU9: 0 | CV9: =SUM(CT9,CU9) -> 3 | CW9: Yellow | CX9: =IF(CW9="Out", VALUE($D9), IF(OR(CZ$3="", CZ$4=""),"", IF(CW9=CW$3, IF(CX$3=CZ$3, $B$3, IF(CX$3>CZ$3, $B$2, $B$4)), IF(CW9=CY$3, IF(CZ$3=CX$3, $B$3, IF(CZ$3>CX$3, $B$2, $B$4)), IF(CW9=CW$4, IF(CX$4=CZ$4, $B$3, IF(CX$4>CZ$4, $B$2, $B$4)), IF(CW9=CY$4, IF(CZ$4=CX$4, $B$3, IF(CZ$4>CX$4, $B$2, $B$4)), "")))))) -> 3 | CY9: 1 | CZ9: =SUM(CX9,CY9) -> 4 | DA9: Yellow | DB9: =IF(DA9="Out", VALUE($D9), IF(OR(DD$3="", DD$4=""),"", IF(DA9=DA$3, IF(DB$3=DD$3, $B$3, IF(DB$3>DD$3, $B$2, $B$4)), IF(DA9=DC$3, IF(DD$3=DB$3, $B$3, IF(DD$3>DB$3, $B$2, $B$4)), IF(DA9=DA$4, IF(DB$4=DD$4, $B$3, IF(DB$4>DD$4, $B$2, $B$4)), IF(DA9=DC$4, IF(DD$4=DB$4, $B$3, IF(DD$4>DB$4, $B$2, $B$4)), "")))))) -> 1 | DC9: 0 | DD9: =SUM(DB9,DC9) -> 1 | DE9: =SUM(CN9,CR9,CV9,CZ9,DD9) -> 14 | DF9: Pink | DG9: =IF(DF9="Out", VALUE($D9), IF(OR(DI$3="", DI$4=""),"", IF(DF9=DF$3, IF(DG$3=DI$3, $B$3, IF(DG$3>DI$3, $B$2, $B$4)), IF(DF9=DH$3, IF(DI$3=DG$3, $B$3, IF(DI$3>DG$3, $B$2, $B$4)), IF(DF9=DF$4, IF(DG$4=DI$4, $B$3, IF(DG$4>DI$4, $B$2, $B$4)), IF(DF9=DH$4, IF(DI$4=DG$4, $B$3, IF(DI$4>DG$4, $B$2, $B$4)), "")))))) -> 0 | DH9: 0 | DI9: =SUM(DG9,DH9) -> 0 | DJ9: Pink | DK9: =IF(DJ9="Out", VALUE($D9), IF(OR(DM$3="", DM$4=""),"", IF(DJ9=DJ$3, IF(DK$3=DM$3, $B$3, IF(DK$3>DM$3, $B$2, $B$4)), IF(DJ9=DL$3, IF(DM$3=DK$3, $B$3, IF(DM$3>DK$3, $B$2, $B$4)), IF(DJ9=DJ$4, IF(DK$4=DM$4, $B$3, IF(DK$4>DM$4, $B$2, $B$4)), IF(DJ9=DL$4, IF(DM$4=DK$4, $B$3, IF(DM$4>DK$4, $B$2, $B$4)), "")))))) -> 3 | DL9: 0 | DM9: =SUM(DK9,DL9) -> 3 | DN9: Jerseys | DO9: =IF(DN9="Out", VALUE($D9), IF(OR(DQ$3="", DQ$4=""),"", IF(DN9=DN$3, IF(DO$3=DQ$3, $B$3, IF(DO$3>DQ$3, $B$2, $B$4)), IF(DN9=DP$3, IF(DQ$3=DO$3, $B$3, IF(DQ$3>DO$3, $B$2, $B$4)), IF(DN9=DN$4, IF(DO$4=DQ$4, $B$3, IF(DO$4>DQ$4, $B$2, $B$4)), IF(DN9=DP$4, IF(DQ$4=DO$4, $B$3, IF(DQ$4>DO$4, $B$2, $B$4)), "")))))) -> 0 | DP9: 0 | DQ9: =SUM(DO9,DP9) -> 0 | DR9: Pink | DS9: =IF(DR9="Out", VALUE($D9), IF(OR(DU$3="", DU$4=""),"", IF(DR9=DR$3, IF(DS$3=DU$3, $B$3, IF(DS$3>DU$3, $B$2, $B$4)), IF(DR9=DT$3, IF(DU$3=DS$3, $B$3, IF(DU$3>DS$3, $B$2, $B$4)), IF(DR9=DR$4, IF(DS$4=DU$4, $B$3, IF(DS$4>DU$4, $B$2, $B$4)), IF(DR9=DT$4, IF(DU$4=DS$4, $B$3, IF(DU$4>DS$4, $B$2, $B$4)), "")))))) -> 3 | DT9: 1 | DU9: =SUM(DS9,DT9) -> 4 | DV9: Blue | DW9: =IF(DV9="Out", VALUE($D9), IF(OR(DY$3="", DY$4=""),"", IF(DV9=DV$3, IF(DW$3=DY$3, $B$3, IF(DW$3>DY$3, $B$2, $B$4)), IF(DV9=DX$3, IF(DY$3=DW$3, $B$3, IF(DY$3>DW$3, $B$2, $B$4)), IF(DV9=DV$4, IF(DW$4=DY$4, $B$3, IF(DW$4>DY$4, $B$2, $B$4)), IF(DV9=DX$4, IF(DY$4=DW$4, $B$3, IF(DY$4>DW$4, $B$2, $B$4)), "")))))) -> 3 | DX9: 1 | DY9: =SUM(DW9,DX9) -> 4 | DZ9: =SUM(DI9,DM9,DQ9,DU9,DY9) -> 11 | EA9: Blue | EB9: =IF(EA9="Out", VALUE($D9), IF(OR(ED$3="", ED$4=""),"", IF(EA9=EA$3, IF(EB$3=ED$3, $B$3, IF(EB$3>ED$3, $B$2, $B$4)), IF(EA9=EC$3, IF(ED$3=EB$3, $B$3, IF(ED$3>EB$3, $B$2, $B$4)), IF(EA9=EA$4, IF(EB$4=ED$4, $B$3, IF(EB$4>ED$4, $B$2, $B$4)), IF(EA9=EC$4, IF(ED$4=EB$4, $B$3, IF(ED$4>EB$4, $B$2, $B$4)), "")))))) -> 1 | EC9: 0 | ED9: =SUM(EB9,EC9) -> 1 | EE9: Pink | EF9: =IF(EE9="Out", VALUE($D9), IF(OR(EH$3="", EH$4=""),"", IF(EE9=EE$3, IF(EF$3=EH$3, $B$3, IF(EF$3>EH$3, $B$2, $B$4)), IF(EE9=EG$3, IF(EH$3=EF$3, $B$3, IF(EH$3>EF$3, $B$2, $B$4)), IF(EE9=EE$4, IF(EF$4=EH$4, $B$3, IF(EF$4>EH$4, $B$2, $B$4)), IF(EE9=EG$4, IF(EH$4=EF$4, $B$3, IF(EH$4>EF$4, $B$2, $B$4)), "")))))) -> 3 | EG9: 1 | EH9: =SUM(EF9,EG9) -> 4 | EI9: Blue | EJ9: =IF(EI9="Out", VALUE($D9), IF(OR(EL$3="", EL$4=""),"", IF(EI9=EI$3, IF(EJ$3=EL$3, $B$3, IF(EJ$3>EL$3, $B$2, $B$4)), IF(EI9=EK$3, IF(EL$3=EJ$3, $B$3, IF(EL$3>EJ$3, $B$2, $B$4)), IF(EI9=EI$4, IF(EJ$4=EL$4, $B$3, IF(EJ$4>EL$4, $B$2, $B$4)), IF(EI9=EK$4, IF(EL$4=EJ$4, $B$3, IF(EL$4>EJ$4, $B$2, $B$4)), "")))))) -> 0 | EK9: 1 | EL9: =SUM(EJ9,EK9) -> 1 | EM9: Yellow | EN9: =IF(EM9="Out", VALUE($D9), IF(OR(EP$3="", EP$4=""),"", IF(EM9=EM$3, IF(EN$3=EP$3, $B$3, IF(EN$3>EP$3, $B$2, $B$4)), IF(EM9=EO$3, IF(EP$3=EN$3, $B$3, IF(EP$3>EN$3, $B$2, $B$4)), IF(EM9=EM$4, IF(EN$4=EP$4, $B$3, IF(EN$4>EP$4, $B$2, $B$4)), IF(EM9=EO$4, IF(EP$4=EN$4, $B$3, IF(EP$4>EN$4, $B$2, $B$4)), "")))))) -> 1 | EO9: 1 | EP9: =SUM(EN9,EO9) -> 2 | EQ9: Pink | ER9: =IF(EQ9="Out", VALUE($D9), IF(OR(ET$3="", ET$4=""),"", IF(EQ9=EQ$3, IF(ER$3=ET$3, $B$3, IF(ER$3>ET$3, $B$2, $B$4)), IF(EQ9=ES$3, IF(ET$3=ER$3, $B$3, IF(ET$3>ER$3, $B$2, $B$4)), IF(EQ9=EQ$4, IF(ER$4=ET$4, $B$3, IF(ER$4>ET$4, $B$2, $B$4)), IF(EQ9=ES$4, IF(ET$4=ER$4, $B$3, IF(ET$4>ER$4, $B$2, $B$4)), "")))))) -> 0 | ES9: 0 | ET9: =SUM(ER9,ES9) -> 0 | EU9: =SUM(ED9,EH9,EL9,EP9,ET9) -> 8 | EV9: Yellow | EW9: =IF(EV9="Out", VALUE($D9), IF(OR(EY$3="", EY$4=""),"", IF(EV9=EV$3, IF(EW$3=EY$3, $B$3, IF(EW$3>EY$3, $B$2, $B$4)), IF(EV9=EX$3, IF(EY$3=EW$3, $B$3, IF(EY$3>EW$3, $B$2, $B$4)), IF(EV9=EV$4, IF(EW$4=EY$4, $B$3, IF(EW$4>EY$4, $B$2, $B$4)), IF(EV9=EX$4, IF(EY$4=EW$4, $B$3, IF(EY$4>EW$4, $B$2, $B$4)), "")))))) -> 1 | EX9: 0 | EY9: =SUM(EW9,EX9) -> 1 | EZ9: Blue | FA9: =IF(EZ9="Out", VALUE($D9), IF(OR(FC$3="", FC$4=""),"", IF(EZ9=EZ$3, IF(FA$3=FC$3, $B$3, IF(FA$3>FC$3, $B$2, $B$4)), IF(EZ9=FB$3, IF(FC$3=FA$3, $B$3, IF(FC$3>FA$3, $B$2, $B$4)), IF(EZ9=EZ$4, IF(FA$4=FC$4, $B$3, IF(FA$4>FC$4, $B$2, $B$4)), IF(EZ9=FB$4, IF(FC$4=FA$4, $B$3, IF(FC$4>FA$4, $B$2, $B$4)), "")))))) -> 0 | FB9: 0 | FC9: =SUM(FA9,FB9) -> 0 | FD9: Pink | FE9: =IF(FD9="Out", VALUE($D9), IF(OR(FG$3="", FG$4=""),"", IF(FD9=FD$3, IF(FE$3=FG$3, $B$3, IF(FE$3>FG$3, $B$2, $B$4)), IF(FD9=FF$3, IF(FG$3=FE$3, $B$3, IF(FG$3>FE$3, $B$2, $B$4)), IF(FD9=FD$4, IF(FE$4=FG$4, $B$3, IF(FE$4>FG$4, $B$2, $B$4)), IF(FD9=FF$4, IF(FG$4=FE$4, $B$3, IF(FG$4>FE$4, $B$2, $B$4)), "")))))) -> 3 | FF9: 2 | FG9: =SUM(FE9,FF9) -> 5 | FH9: Jerseys | FI9: =IF(FH9="Out", VALUE($D9), IF(OR(FK$3="", FK$4=""),"", IF(FH9=FH$3, IF(FI$3=FK$3, $B$3, IF(FI$3>FK$3, $B$2, $B$4)), IF(FH9=FJ$3, IF(FK$3=FI$3, $B$3, IF(FK$3>FI$3, $B$2, $B$4)), IF(FH9=FH$4, IF(FI$4=FK$4, $B$3, IF(FI$4>FK$4, $B$2, $B$4)), IF(FH9=FJ$4, IF(FK$4=FI$4, $B$3, IF(FK$4>FI$4, $B$2, $B$4)), "")))))) -> 1 | FJ9: 2 | FK9: =SUM(FI9,FJ9) -> 3 | FL9: =SUM(EU9,EY9,FC9,FG9,FK9) -> 17
A10: Breton | B10: Amelia | C10: =AVERAGEIF($7:$7,"Goals",10:10) -> 1.9117647 | D10: =VALUE(AVERAGEIF($E$7:$ZZ$7,"Team Pts",$E10:$ZZ10)) -> 2.0588235 | E10: Blue | F10: =IF(OR(H$3="", H$4=""),"", IF(E10=E$3, IF(F$3=H$3, B$3, IF(F$3>H$3, B$2, B$4)), IF(E10=G$3, IF(H$3=F$3, B$3, IF(H$3>F$3, B$2, B$4)), IF(E10=E$4, IF(F$4=H$4, B$3, IF(F$4>H$4, B$2, B$4)), IF(E10=G$4, IF(H$4=F$4, B$3, IF(H$4>F$4, B$2, B$4)), ""))))) -> 3 | G10: 0 | H10: =SUM(F10,G10) -> 3 | I10: Yellow | J10: =IF(OR(L$3="", L$4=""),"", IF(I10=I$3, IF(J$3=L$3, B$3, IF(J$3>L$3, B$2, B$4)), IF(I10=K$3, IF(L$3=J$3, B$3, IF(L$3>J$3, B$2, B$4)), IF(I10=I$4, IF(J$4=L$4, B$3, IF(J$4>L$4, B$2, B$4)), IF(I10=K$4, IF(L$4=J$4, B$3, IF(L$4>J$4, B$2, B$4)), ""))))) -> 3 | K10: 3 | L10: =SUM(J10,K10) -> 6 | M10: Yellow | N10: =IF(OR(P$3="", P$4=""),"", IF(M10=M$3, IF(N$3=P$3, B$3, IF(N$3>P$3, B$2, B$4)), IF(M10=O$3, IF(P$3=N$3, B$3, IF(P$3>N$3, B$2, B$4)), IF(M10=M$4, IF(N$4=P$4, B$3, IF(N$4>P$4, B$2, B$4)), IF(M10=O$4, IF(P$4=N$4, B$3, IF(P$4>N$4, B$2, B$4)), ""))))) -> 3 | O10: 2 | P10: =SUM(N10,O10) -> 5 | Q10: Jerseys | R10: =IF(OR(T$3="", T$4=""),"", IF(Q10=Q$3, IF(R$3=T$3, B$3, IF(R$3>T$3, B$2, B$4)), IF(Q10=S$3, IF(T$3=R$3, B$3, IF(T$3>R$3, B$2, B$4)), IF(Q10=Q$4, IF(R$4=T$4, B$3, IF(R$4>T$4, B$2, B$4)), IF(Q10=S$4, IF(T$4=R$4, B$3, IF(T$4>R$4, B$2, B$4)), ""))))) -> 3 | S10: 2 | T10: =SUM(R10,S10) -> 5 | U10: Jerseys | V10: =IF(OR(X$3="", X$4=""),"", IF(U10=U$3, IF(V$3=X$3, B$3, IF(V$3>X$3, B$2, B$4)), IF(U10=W$3, IF(X$3=V$3, B$3, IF(X$3>V$3, B$2, B$4)), IF(U10=U$4, IF(V$4=X$4, B$3, IF(V$4>X$4, B$2, B$4)), IF(U10=W$4, IF(X$4=V$4, B$3, IF(X$4>V$4, B$2, B$4)), ""))))) -> 0 | W10: 1 | X10: =SUM(V10,W10) -> 1 | Y10: =SUM(H10,L10,P10,T10,X10) -> 20 | Z10: Blue | AA10: =IF(Z10="Out", VALUE($D10), IF(OR(AC$3="", AC$4=""),"", IF(Z10=Z$3, IF(AA$3=AC$3, $B$3, IF(AA$3>AC$3, $B$2, $B$4)), IF(Z10=AB$3, IF(AC$3=AA$3, $B$3, IF(AC$3>AA$3, $B$2, $B$4)), IF(Z10=Z$4, IF(AA$4=AC$4, $B$3, IF(AA$4>AC$4, $B$2, $B$4)), IF(Z10=AB$4, IF(AC$4=AA$4, $B$3, IF(AC$4>AA$4, $B$2, $B$4)), "")))))) -> 3 | AB10: 3 | AC10: =SUM(AA10,AB10) -> 6 | AD10: Pink | AE10: =IF(AD10="Out", VALUE($D10), IF(OR(AG$3="", AG$4=""),"", IF(AD10=AD$3, IF(AE$3=AG$3, $B$3, IF(AE$3>AG$3, $B$2, $B$4)), IF(AD10=AF$3, IF(AG$3=AE$3, $B$3, IF(AG$3>AE$3, $B$2, $B$4)), IF(AD10=AD$4, IF(AE$4=AG$4, $B$3, IF(AE$4>AG$4, $B$2, $B$4)), IF(AD10=AF$4, IF(AG$4=AE$4, $B$3, IF(AG$4>AE$4, $B$2, $B$4)), "")))))) -> 3 | AF10: 1 | AG10: =SUM(AE10,AF10) -> 4 | AH10: Jerseys | AI10: =IF(OR(AK$3="", AK$4=""),"", IF(AH10=AH$3, IF(AI$3=AK$3, $B$3, IF(AI$3>AK$3, $B$2, $B$4)), IF(AH10=AJ$3, IF(AK$3=AI$3, $B$3, IF(AK$3>AI$3, $B$2, $B$4)), IF(AH10=AH$4, IF(AI$4=AK$4, $B$3, IF(AI$4>AK$4, $B$2, $B$4)), IF(AH10=AJ$4, IF(AK$4=AI$4, $B$3, IF(AK$4>AI$4, $B$2, $B$4)), ""))))) -> 3 | AJ10: 2 | AK10: =SUM(AI10,AJ10) -> 5 | AL10: Jerseys | AM10: =IF(OR(AO$3="", AO$4=""),"", IF(AL10=AL$3, IF(AM$3=AO$3, $B$3, IF(AM$3>AO$3, $B$2, $B$4)), IF(AL10=AN$3, IF(AO$3=AM$3, $B$3, IF(AO$3>AM$3, $B$2, $B$4)), IF(AL10=AL$4, IF(AM$4=AO$4, $B$3, IF(AM$4>AO$4, $B$2, $B$4)), IF(AL10=AN$4, IF(AO$4=AM$4, $B$3, IF(AO$4>AM$4, $B$2, $B$4)), ""))))) -> 1 | AN10: 3 | AO10: =SUM(AM10,AN10) -> 4 | AP10: Blue | AQ10: =IF(OR(AS$3="", AS$4=""),"", IF(AP10=AP$3, IF(AQ$3=AS$3, $B$3, IF(AQ$3>AS$3, $B$2, $B$4)), IF(AP10=AR$3, IF(AS$3=AQ$3, $B$3, IF(AS$3>AQ$3, $B$2, $B$4)), IF(AP10=AP$4, IF(AQ$4=AS$4, $B$3, IF(AQ$4>AS$4, $B$2, $B$4)), IF(AP10=AR$4, IF(AS$4=AQ$4, $B$3, IF(AS$4>AQ$4, $B$2, $B$4)), ""))))) -> 3 | AR10: 3 | AS10: =SUM(AQ10,AR10) -> 6 | AT10: =SUM(AC10,AG10,AK10,AO10,AS10) -> 25 | AU10: Pink | AV10: =IF(AU10="Out", VALUE($D10), IF(OR(AX$3="", AX$4=""),"", IF(AU10=AU$3, IF(AV$3=AX$3, $B$3, IF(AV$3>AX$3, $B$2, $B$4)), IF(AU10=AW$3, IF(AX$3=AV$3, $B$3, IF(AX$3>AV$3, $B$2, $B$4)), IF(AU10=AU$4, IF(AV$4=AX$4, $B$3, IF(AV$4>AX$4, $B$2, $B$4)), IF(AU10=AW$4, IF(AX$4=AV$4, $B$3, IF(AX$4>AV$4, $B$2, $B$4)), "")))))) -> 0 | AW10: 0 | AX10: =SUM(AV10,AW10) -> 0 | AY10: Pink | AZ10: =IF(AY10="Out", VALUE($D10), IF(OR(BB$3="", BB$4=""),"", IF(AY10=AY$3, IF(AZ$3=BB$3, $B$3, IF(AZ$3>BB$3, $B$2, $B$4)), IF(AY10=BA$3, IF(BB$3=AZ$3, $B$3, IF(BB$3>AZ$3, $B$2, $B$4)), IF(AY10=AY$4, IF(AZ$4=BB$4, $B$3, IF(AZ$4>BB$4, $B$2, $B$4)), IF(AY10=BA$4, IF(BB$4=AZ$4, $B$3, IF(BB$4>AZ$4, $B$2, $B$4)), "")))))) -> 1 | BA10: 3 | BB10: =SUM(AZ10,BA10) -> 4 | BC10: Pink | BD10: =IF(BC10="Out", VALUE($D10), IF(OR(BF$3="", BF$4=""),"", IF(BC10=BC$3, IF(BD$3=BF$3, $B$3, IF(BD$3>BF$3, $B$2, $B$4)), IF(BC10=BE$3, IF(BF$3=BD$3, $B$3, IF(BF$3>BD$3, $B$2, $B$4)), IF(BC10=BC$4, IF(BD$4=BF$4, $B$3, IF(BD$4>BF$4, $B$2, $B$4)), IF(BC10=BE$4, IF(BF$4=BD$4, $B$3, IF(BF$4>BD$4, $B$2, $B$4)), "")))))) -> 3 | BE10: 3 | BF10: =SUM(BD10,BE10) -> 6 | BG10: Jerseys | BH10: =IF(BG10="Out", VALUE($D10), IF(OR(BJ$3="", BJ$4=""),"", IF(BG10=BG$3, IF(BH$3=BJ$3, $B$3, IF(BH$3>BJ$3, $B$2, $B$4)), IF(BG10=BI$3, IF(BJ$3=BH$3, $B$3, IF(BJ$3>BH$3, $B$2, $B$4)), IF(BG10=BG$4, IF(BH$4=BJ$4, $B$3, IF(BH$4>BJ$4, $B$2, $B$4)), IF(BG10=BI$4, IF(BJ$4=BH$4, $B$3, IF(BJ$4>BH$4, $B$2, $B$4)), "")))))) -> 0 | BI10: 1 | BJ10: =SUM(BH10,BI10) -> 1 | BK10: Yellow | BL10: =IF(BK10="Out", VALUE($D10), IF(OR(BN$3="", BN$4=""),"", IF(BK10=BK$3, IF(BL$3=BN$3, $B$3, IF(BL$3>BN$3, $B$2, $B$4)), IF(BK10=BM$3, IF(BN$3=BL$3, $B$3, IF(BN$3>BL$3, $B$2, $B$4)), IF(BK10=BK$4, IF(BL$4=BN$4, $B$3, IF(BL$4>BN$4, $B$2, $B$4)), IF(BK10=BM$4, IF(BN$4=BL$4, $B$3, IF(BN$4>BL$4, $B$2, $B$4)), "")))))) -> 0 | BM10: 1 | BN10: =SUM(BL10,BM10) -> 1 | BO10: =SUM(AX10,BB10,BF10,BJ10,BN10) -> 12 | BP10: Yellow | BQ10: =IF(BP10="Out", VALUE($D10), IF(OR(BS$3="", BS$4=""),"", IF(BP10=BP$3, IF(BQ$3=BS$3, $B$3, IF(BQ$3>BS$3, $B$2, $B$4)), IF(BP10=BR$3, IF(BS$3=BQ$3, $B$3, IF(BS$3>BQ$3, $B$2, $B$4)), IF(BP10=BP$4, IF(BQ$4=BS$4, $B$3, IF(BQ$4>BS$4, $B$2, $B$4)), IF(BP10=BR$4, IF(BS$4=BQ$4, $B$3, IF(BS$4>BQ$4, $B$2, $B$4)), "")))))) -> 3 | BR10: 3 | BS10: =SUM(BQ10,BR10) -> 6 | BT10: Pink | BU10: =IF(BT10="Out", VALUE($D10), IF(OR(BW$3="", BW$4=""),"", IF(BT10=BT$3, IF(BU$3=BW$3, $B$3, IF(BU$3>BW$3, $B$2, $B$4)), IF(BT10=BV$3, IF(BW$3=BU$3, $B$3, IF(BW$3>BU$3, $B$2, $B$4)), IF(BT10=BT$4, IF(BU$4=BW$4, $B$3, IF(BU$4>BW$4, $B$2, $B$4)), IF(BT10=BV$4, IF(BW$4=BU$4, $B$3, IF(BW$4>BU$4, $B$2, $B$4)), "")))))) -> 3 | BV10: 0 | BW10: =SUM(BU10,BV10) -> 3 | BX10: Blue | BY10: =IF(BX10="Out", VALUE($D10), IF(OR(CA$3="", CA$4=""),"", IF(BX10=BX$3, IF(BY$3=CA$3, $B$3, IF(BY$3>CA$3, $B$2, $B$4)), IF(BX10=BZ$3, IF(CA$3=BY$3, $B$3, IF(CA$3>BY$3, $B$2, $B$4)), IF(BX10=BX$4, IF(BY$4=CA$4, $B$3, IF(BY$4>CA$4, $B$2, $B$4)), IF(BX10=BZ$4, IF(CA$4=BY$4, $B$3, IF(CA$4>BY$4, $B$2, $B$4)), "")))))) -> 3 | BZ10: 3 | CA10: =SUM(BY10,BZ10) -> 6 | CB10: Pink | CC10: =IF(CB10="Out", VALUE($D10), IF(OR(CE$3="", CE$4=""),"", IF(CB10=CB$3, IF(CC$3=CE$3, $B$3, IF(CC$3>CE$3, $B$2, $B$4)), IF(CB10=CD$3, IF(CE$3=CC$3, $B$3, IF(CE$3>CC$3, $B$2, $B$4)), IF(CB10=CB$4, IF(CC$4=CE$4, $B$3, IF(CC$4>CE$4, $B$2, $B$4)), IF(CB10=CD$4, IF(CE$4=CC$4, $B$3, IF(CE$4>CC$4, $B$2, $B$4)), "")))))) -> 3 | CD10: 3 | CE10: =SUM(CC10,CD10) -> 6 | CF10: Blue | CG10: =IF(CF10="Out", VALUE($D10), IF(OR(CI$3="", CI$4=""),"", IF(CF10=CF$3, IF(CG$3=CI$3, $B$3, IF(CG$3>CI$3, $B$2, $B$4)), IF(CF10=CH$3, IF(CI$3=CG$3, $B$3, IF(CI$3>CG$3, $B$2, $B$4)), IF(CF10=CF$4, IF(CG$4=CI$4, $B$3, IF(CG$4>CI$4, $B$2, $B$4)), IF(CF10=CH$4, IF(CI$4=CG$4, $B$3, IF(CI$4>CG$4, $B$2, $B$4)), "")))))) -> 0 | CH10: 2 | CI10: =SUM(CG10,CH10) -> 2 | CJ10: =SUM(BS10,BW10,CA10,CE10,CI10) -> 23 | CK10: Out | CL10: =IF(CK10="Out", VALUE($D10), IF(OR(CN$3="", CN$4=""),"", IF(CK10=CK$3, IF(CL$3=CN$3, $B$3, IF(CL$3>CN$3, $B$2, $B$4)), IF(CK10=CM$3, IF(CN$3=CL$3, $B$3, IF(CN$3>CL$3, $B$2, $B$4)), IF(CK10=CK$4, IF(CL$4=CN$4, $B$3, IF(CL$4>CN$4, $B$2, $B$4)), IF(CK10=CM$4, IF(CN$4=CL$4, $B$3, IF(CN$4>CL$4, $B$2, $B$4)), "")))))) -> 2.0588235 | CM10: =IF(CK10="Out", $C10) -> 1.9117647 | CN10: =SUM(CL10,CM10) -> 3.9705882 | CO10: Out | CP10: =IF(CO10="Out", VALUE($D10), IF(OR(CR$3="", CR$4=""),"", IF(CO10=CO$3, IF(CP$3=CR$3, $B$3, IF(CP$3>CR$3, $B$2, $B$4)), IF(CO10=CQ$3, IF(CR$3=CP$3, $B$3, IF(CR$3>CP$3, $B$2, $B$4)), IF(CO10=CO$4, IF(CP$4=CR$4, $B$3, IF(CP$4>CR$4, $B$2, $B$4)), IF(CO10=CQ$4, IF(CR$4=CP$4, $B$3, IF(CR$4>CP$4, $B$2, $B$4)), "")))))) -> 2.0588235 | CQ10: =IF(CO10="Out", $C10) -> 1.9117647 | CR10: =SUM(CP10,CQ10) -> 3.9705882 | CS10: Out | CT10: =IF(CS10="Out", VALUE($D10), IF(OR(CV$3="", CV$4=""),"", IF(CS10=CS$3, IF(CT$3=CV$3, $B$3, IF(CT$3>CV$3, $B$2, $B$4)), IF(CS10=CU$3, IF(CV$3=CT$3, $B$3, IF(CV$3>CT$3, $B$2, $B$4)), IF(CS10=CS$4, IF(CT$4=CV$4, $B$3, IF(CT$4>CV$4, $B$2, $B$4)), IF(CS10=CU$4, IF(CV$4=CT$4, $B$3, IF(CV$4>CT$4, $B$2, $B$4)), "")))))) -> 2.0588235 | CU10: =IF(CS10="Out", $C10) -> 1.9117647 | CV10: =SUM(CT10,CU10) -> 3.9705882 | CW10: Out | CX10: =IF(CW10="Out", VALUE($D10), IF(OR(CZ$3="", CZ$4=""),"", IF(CW10=CW$3, IF(CX$3=CZ$3, $B$3, IF(CX$3>CZ$3, $B$2, $B$4)), IF(CW10=CY$3, IF(CZ$3=CX$3, $B$3, IF(CZ$3>CX$3, $B$2, $B$4)), IF(CW10=CW$4, IF(CX$4=CZ$4, $B$3, IF(CX$4>CZ$4, $B$2, $B$4)), IF(CW10=CY$4, IF(CZ$4=CX$4, $B$3, IF(CZ$4>CX$4, $B$2, $B$4)), "")))))) -> 2.0588235 | CY10: =IF(CW10="Out", $C10) -> 1.9117647 | CZ10: =SUM(CX10,CY10) -> 3.9705882 | DA10: Out | DB10: =IF(DA10="Out", VALUE($D10), IF(OR(DD$3="", DD$4=""),"", IF(DA10=DA$3, IF(DB$3=DD$3, $B$3, IF(DB$3>DD$3, $B$2, $B$4)), IF(DA10=DC$3, IF(DD$3=DB$3, $B$3, IF(DD$3>DB$3, $B$2, $B$4)), IF(DA10=DA$4, IF(DB$4=DD$4, $B$3, IF(DB$4>DD$4, $B$2, $B$4)), IF(DA10=DC$4, IF(DD$4=DB$4, $B$3, IF(DD$4>DB$4, $B$2, $B$4)), "")))))) -> 2.0588235 | DC10: =IF(DA10="Out", $C10) -> 1.9117647 | DD10: =SUM(DB10,DC10) -> 3.9705882 | DE10: =SUM(CN10,CR10,CV10,CZ10,DD10) -> 19.852941 | DF10: Yellow | DG10: =IF(DF10="Out", VALUE($D10), IF(OR(DI$3="", DI$4=""),"", IF(DF10=DF$3, IF(DG$3=DI$3, $B$3, IF(DG$3>DI$3, $B$2, $B$4)), IF(DF10=DH$3, IF(DI$3=DG$3, $B$3, IF(DI$3>DG$3, $B$2, $B$4)), IF(DF10=DF$4, IF(DG$4=DI$4, $B$3, IF(DG$4>DI$4, $B$2, $B$4)), IF(DF10=DH$4, IF(DI$4=DG$4, $B$3, IF(DI$4>DG$4, $B$2, $B$4)), "")))))) -> 0 | DH10: 1 | DI10: =SUM(DG10,DH10) -> 1 | DJ10: Pink | DK10: =IF(DJ10="Out", VALUE($D10), IF(OR(DM$3="", DM$4=""),"", IF(DJ10=DJ$3, IF(DK$3=DM$3, $B$3, IF(DK$3>DM$3, $B$2, $B$4)), IF(DJ10=DL$3, IF(DM$3=DK$3, $B$3, IF(DM$3>DK$3, $B$2, $B$4)), IF(DJ10=DJ$4, IF(DK$4=DM$4, $B$3, IF(DK$4>DM$4, $B$2, $B$4)), IF(DJ10=DL$4, IF(DM$4=DK$4, $B$3, IF(DM$4>DK$4, $B$2, $B$4)), "")))))) -> 3 | DL10: 4 | DM10: =SUM(DK10,DL10) -> 7 | DN10: Yellow | DO10: =IF(DN10="Out", VALUE($D10), IF(OR(DQ$3="", DQ$4=""),"", IF(DN10=DN$3, IF(DO$3=DQ$3, $B$3, IF(DO$3>DQ$3, $B$2, $B$4)), IF(DN10=DP$3, IF(DQ$3=DO$3, $B$3, IF(DQ$3>DO$3, $B$2, $B$4)), IF(DN10=DN$4, IF(DO$4=DQ$4, $B$3, IF(DO$4>DQ$4, $B$2, $B$4)), IF(DN10=DP$4, IF(DQ$4=DO$4, $B$3, IF(DQ$4>DO$4, $B$2, $B$4)), "")))))) -> 3 | DP10: 2 | DQ10: =SUM(DO10,DP10) -> 5 | DR10: Pink | DS10: =IF(DR10="Out", VALUE($D10), IF(OR(DU$3="", DU$4=""),"", IF(DR10=DR$3, IF(DS$3=DU$3, $B$3, IF(DS$3>DU$3, $B$2, $B$4)), IF(DR10=DT$3, IF(DU$3=DS$3, $B$3, IF(DU$3>DS$3, $B$2, $B$4)), IF(DR10=DR$4, IF(DS$4=DU$4, $B$3, IF(DS$4>DU$4, $B$2, $B$4)), IF(DR10=DT$4, IF(DU$4=DS$4, $B$3, IF(DU$4>DS$4, $B$2, $B$4)), "")))))) -> 3 | DT10: 4 | DU10: =SUM(DS10,DT10) -> 7 | DV10: Blue | DW10: =IF(DV10="Out", VALUE($D10), IF(OR(DY$3="", DY$4=""),"", IF(DV10=DV$3, IF(DW$3=DY$3, $B$3, IF(DW$3>DY$3, $B$2, $B$4)), IF(DV10=DX$3, IF(DY$3=DW$3, $B$3, IF(DY$3>DW$3, $B$2, $B$4)), IF(DV10=DV$4, IF(DW$4=DY$4, $B$3, IF(DW$4>DY$4, $B$2, $B$4)), IF(DV10=DX$4, IF(DY$4=DW$4, $B$3, IF(DY$4>DW$4, $B$2, $B$4)), "")))))) -> 3 | DX10: 2 | DY10: =SUM(DW10,DX10) -> 5 | DZ10: =SUM(DI10,DM10,DQ10,DU10,DY10) -> 25 | EA10: Yellow | EB10: =IF(EA10="Out", VALUE($D10), IF(OR(ED$3="", ED$4=""),"", IF(EA10=EA$3, IF(EB$3=ED$3, $B$3, IF(EB$3>ED$3, $B$2, $B$4)), IF(EA10=EC$3, IF(ED$3=EB$3, $B$3, IF(ED$3>EB$3, $B$2, $B$4)), IF(EA10=EA$4, IF(EB$4=ED$4, $B$3, IF(EB$4>ED$4, $B$2, $B$4)), IF(EA10=EC$4, IF(ED$4=EB$4, $B$3, IF(ED$4>EB$4, $B$2, $B$4)), "")))))) -> 1 | EC10: 2 | ED10: =SUM(EB10,EC10) -> 3 | EE10: Pink | EF10: =IF(EE10="Out", VALUE($D10), IF(OR(EH$3="", EH$4=""),"", IF(EE10=EE$3, IF(EF$3=EH$3, $B$3, IF(EF$3>EH$3, $B$2, $B$4)), IF(EE10=EG$3, IF(EH$3=EF$3, $B$3, IF(EH$3>EF$3, $B$2, $B$4)), IF(EE10=EE$4, IF(EF$4=EH$4, $B$3, IF(EF$4>EH$4, $B$2, $B$4)), IF(EE10=EG$4, IF(EH$4=EF$4, $B$3, IF(EH$4>EF$4, $B$2, $B$4)), "")))))) -> 3 | EG10: 1 | EH10: =SUM(EF10,EG10) -> 4 | EI10: Jerseys | EJ10: =IF(EI10="Out", VALUE($D10), IF(OR(EL$3="", EL$4=""),"", IF(EI10=EI$3, IF(EJ$3=EL$3, $B$3, IF(EJ$3>EL$3, $B$2, $B$4)), IF(EI10=EK$3, IF(EL$3=EJ$3, $B$3, IF(EL$3>EJ$3, $B$2, $B$4)), IF(EI10=EI$4, IF(EJ$4=EL$4, $B$3, IF(EJ$4>EL$4, $B$2, $B$4)), IF(EI10=EK$4, IF(EL$4=EJ$4, $B$3, IF(EL$4>EJ$4, $B$2, $B$4)), "")))))) -> 3 | EK10: 1 | EL10: =SUM(EJ10,EK10) -> 4 | EM10: Blue | EN10: =IF(EM10="Out", VALUE($D10), IF(OR(EP$3="", EP$4=""),"", IF(EM10=EM$3, IF(EN$3=EP$3, $B$3, IF(EN$3>EP$3, $B$2, $B$4)), IF(EM10=EO$3, IF(EP$3=EN$3, $B$3, IF(EP$3>EN$3, $B$2, $B$4)), IF(EM10=EM$4, IF(EN$4=EP$4, $B$3, IF(EN$4>EP$4, $B$2, $B$4)), IF(EM10=EO$4, IF(EP$4=EN$4, $B$3, IF(EP$4>EN$4, $B$2, $B$4)), "")))))) -> 3 | EO10: 3 | EP10: =SUM(EN10,EO10) -> 6 | EQ10: Blue | ER10: =IF(EQ10="Out", VALUE($D10), IF(OR(ET$3="", ET$4=""),"", IF(EQ10=EQ$3, IF(ER$3=ET$3, $B$3, IF(ER$3>ET$3, $B$2, $B$4)), IF(EQ10=ES$3, IF(ET$3=ER$3, $B$3, IF(ET$3>ER$3, $B$2, $B$4)), IF(EQ10=EQ$4, IF(ER$4=ET$4, $B$3, IF(ER$4>ET$4, $B$2, $B$4)), IF(EQ10=ES$4, IF(ET$4=ER$4, $B$3, IF(ET$4>ER$4, $B$2, $B$4)), "")))))) -> 3 | ES10: 0 | ET10: =SUM(ER10,ES10) -> 3 | EU10: =SUM(ED10,EH10,EL10,EP10,ET10) -> 20 | EV10: Pink | EW10: =IF(EV10="Out", VALUE($D10), IF(OR(EY$3="", EY$4=""),"", IF(EV10=EV$3, IF(EW$3=EY$3, $B$3, IF(EW$3>EY$3, $B$2, $B$4)), IF(EV10=EX$3, IF(EY$3=EW$3, $B$3, IF(EY$3>EW$3, $B$2, $B$4)), IF(EV10=EV$4, IF(EW$4=EY$4, $B$3, IF(EW$4>EY$4, $B$2, $B$4)), IF(EV10=EX$4, IF(EY$4=EW$4, $B$3, IF(EY$4>EW$4, $B$2, $B$4)), "")))))) -> 0 | EX10: 0 | EY10: =SUM(EW10,EX10) -> 0 | EZ10: Jerseys | FA10: =IF(EZ10="Out", VALUE($D10), IF(OR(FC$3="", FC$4=""),"", IF(EZ10=EZ$3, IF(FA$3=FC$3, $B$3, IF(FA$3>FC$3, $B$2, $B$4)), IF(EZ10=FB$3, IF(FC$3=FA$3, $B$3, IF(FC$3>FA$3, $B$2, $B$4)), IF(EZ10=EZ$4, IF(FA$4=FC$4, $B$3, IF(FA$4>FC$4, $B$2, $B$4)), IF(EZ10=FB$4, IF(FC$4=FA$4, $B$3, IF(FC$4>FA$4, $B$2, $B$4)), "")))))) -> 3 | FB10: 0 | FC10: =SUM(FA10,FB10) -> 3 | FD10: Yellow | FE10: =IF(FD10="Out", VALUE($D10), IF(OR(FG$3="", FG$4=""),"", IF(FD10=FD$3, IF(FE$3=FG$3, $B$3, IF(FE$3>FG$3, $B$2, $B$4)), IF(FD10=FF$3, IF(FG$3=FE$3, $B$3, IF(FG$3>FE$3, $B$2, $B$4)), IF(FD10=FD$4, IF(FE$4=FG$4, $B$3, IF(FE$4>FG$4, $B$2, $B$4)), IF(FD10=FF$4, IF(FG$4=FE$4, $B$3, IF(FG$4>FE$4, $B$2, $B$4)), "")))))) -> 0 | FF10: 1 | FG10: =SUM(FE10,FF10) -> 1 | FH10: Jerseys | FI10: =IF(FH10="Out", VALUE($D10), IF(OR(FK$3="", FK$4=""),"", IF(FH10=FH$3, IF(FI$3=FK$3, $B$3, IF(FI$3>FK$3, $B$2, $B$4)), IF(FH10=FJ$3, IF(FK$3=FI$3, $B$3, IF(FK$3>FI$3, $B$2, $B$4)), IF(FH10=FH$4, IF(FI$4=FK$4, $B$3, IF(FI$4>FK$4, $B$2, $B$4)), IF(FH10=FJ$4, IF(FK$4=FI$4, $B$3, IF(FK$4>FI$4, $B$2, $B$4)), "")))))) -> 1 | FJ10: 5 | FK10: =SUM(FI10,FJ10) -> 6 | FL10: =SUM(EU10,EY10,FC10,FG10,FK10) -> 30
